Workbook

Sheet 作業報告書
B2: 修 理 作 業 報 告 書
B5: 船名 | W5: 科目 | AZ5: 型名 | BS5: 製造者
B9: 月／日 | E9: 移 動 | H9: 作業内 (平日) | K9: 作業外 (平日) | N9: 休日 | Q9: 作業者 | T9: 場 所 | W9: 作 業 内 容 | CF9: 所要時間 作業者1 | CP9: 所要時間 作業者2 | CZ9: 所要時間 作業者3 | DJ9: 所要時間 作業者4 | DT9: 所要時間 作業者5
CF11: 移動 | CJ11: =IF(Q11="作業者1",E14-E11,0) | CP11: 移動 | CT11: =IF(Q11="作業者2",E14-E11,0) | CZ11: 移動 | DD11: =IF(Q11="作業者3",E14-E11,0) | DJ11: 移動 | DN11: =IF(Q11="作業者4",E14-E11,0) | DT11: 移動 | DX11: =IF(Q11="作業者5",E14-E11,0)
F12: ～ | I12: ～ | L12: ～ | O12: ～ | CF12: 時間内 | CJ12: =IF(Q11="作業者1",H14-H11,0) | CP12: 時間内 | CT12: =IF(Q11="作業者2",H14-H11,0) | CZ12: 時間内 | DD12: =IF(Q11="作業者3",H14-H11,0) | DJ12: 時間内 | DN12: =IF(Q11="作業者4",H14-H11,0) | DT12: 時間内 | DX12: =IF(Q11="作業者5",H14-H11,0)
CF13: 時間外 | CJ13: =IF(Q11="作業者1",K14-K11,0) | CP13: 時間外 | CT13: =IF(Q11="作業者2",K14-K11,0) | CZ13: 時間外 | DD13: =IF(Q11="作業者3",K14-K11,0) | DJ13: 時間外 | DN13: =IF(Q11="作業者4",K14-K11,0) | DT13: 時間外 | DX13: =IF(Q11="作業者5",K14-K11,0)
CF14: 休日 | CJ14: =IF(Q11="作業者1",N14-N11,0) | CP14: 休日 | CT14: =IF(Q11="作業者2",N14-N11,0) | CZ14: 休日 | DD14: =IF(Q11="作業者3",N14-N11,0) | DJ14: 休日 | DN14: =IF(Q11="作業者4",N14-N11,0) | DT14: 休日 | DX14: =IF(Q11="作業者5",N14-N11,0)
CF15: 移動 | CJ15: =IF(Q15="作業者1",E18-E15,0) | CP15: 移動 | CT15: =IF(Q15="作業者2",E18-E15,0) | CZ15: 移動 | DD15: =IF(Q15="作業者3",E18-E15,0) | DJ15: 移動 | DN15: =IF(Q15="作業者4",E18-E15,0) | DT15: 移動 | DX15: =IF(Q15="作業者5",E18-E15,0)
F16: ～ | I16: ～ | L16: ～ | O16: ～ | CF16: 時間内 | CJ16: =IF(Q15="作業者1",H18-H15,0) | CP16: 時間内 | CT16: =IF(Q15="作業者2",H18-H15,0) | CZ16: 時間内 | DD16: =IF(Q15="作業者3",H18-H15,0) | DJ16: 時間内 | DN16: =IF(Q15="作業者4",H18-H15,0) | DT16: 時間内 | DX16: =IF(Q15="作業者5",H18-H15,0)
CF17: 時間外 | CJ17: =IF(Q15="作業者1",K18-K15,0) | CP17: 時間外 | CT17: =IF(Q15="作業者2",K18-K15,0) | CZ17: 時間外 | DD17: =IF(Q15="作業者3",K18-K15,0) | DJ17: 時間外 | DN17: =IF(Q15="作業者4",K18-K15,0) | DT17: 時間外 | DX17: =IF(Q15="作業者5",K18-K15,0)
CF18: 休日 | CJ18: =IF(Q15="作業者1",N18-N15,0) | CP18: 休日 | CT18: =IF(Q15="作業者2",N18-N15,0) | CZ18: 休日 | DD18: =IF(Q15="作業者3",N18-N15,0) | DJ18: 休日 | DN18: =IF(Q15="作業者4",N18-N15,0) | DT18: 休日 | DX18: =IF(Q15="作業者5",N18-N15,0)
CF19: 移動 | CJ19: =IF(Q19="作業者1",E22-E19,0) | CP19: 移動 | CT19: =IF(Q19="作業者2",E22-E19,0) | CZ19: 移動 | DD19: =IF(Q19="作業者3",E22-E19,0) | DJ19: 移動 | DN19: =IF(Q19="作業者4",E22-E19,0) | DT19: 移動 | DX19: =IF(Q19="作業者5",E22-E19,0)
F20: ～ | I20: ～ | L20: ～ | O20: ～ | CF20: 時間内 | CJ20: =IF(Q19="作業者1",H22-H19,0) | CP20: 時間内 | CT20: =IF(Q19="作業者2",H22-H19,0) | CZ20: 時間内 | DD20: =IF(Q19="作業者3",H22-H19,0) | DJ20: 時間内 | DN20: =IF(Q19="作業者4",H22-H19,0) | DT20: 時間内 | DX20: =IF(Q19="作業者5",H22-H19,0)
CF21: 時間外 | CJ21: =IF(Q19="作業者1",K22-K19,0) | CP21: 時間外 | CT21: =IF(Q19="作業者2",K22-K19,0) | CZ21: 時間外 | DD21: =IF(Q19="作業者3",K22-K19,0) | DJ21: 時間外 | DN21: =IF(Q19="作業者4",K22-K19,0) | DT21: 時間外 | DX21: =IF(Q19="作業者5",K22-K19,0)
CF22: 休日 | CJ22: =IF(Q19="作業者1",N22-N19,0) | CP22: 休日 | CT22: =IF(Q19="作業者2",N22-N19,0) | CZ22: 休日 | DD22: =IF(Q19="作業者3",N22-N19,0) | DJ22: 休日 | DN22: =IF(Q19="作業者4",N22-N19,0) | DT22: 休日 | DX22: =IF(Q19="作業者5",N22-N19,0)
CF23: 移動 | CJ23: =IF(Q23="作業者1",E26-E23,0) | CP23: 移動 | CT23: =IF(Q23="作業者2",E26-E23,0) | CZ23: 移動 | DD23: =IF(Q23="作業者3",E26-E23,0) | DJ23: 移動 | DN23: =IF(Q23="作業者4",E26-E23,0) | DT23: 移動 | DX23: =IF(Q23="作業者5",E26-E23,0)
F24: ～ | I24: ～ | L24: ～ | O24: ～ | CF24: 時間内 | CJ24: =IF(Q23="作業者1",H26-H23,0) | CP24: 時間内 | CT24: =IF(Q23="作業者2",H26-H23,0) | CZ24: 時間内 | DD24: =IF(Q23="作業者3",H26-H23,0) | DJ24: 時間内 | DN24: =IF(Q23="作業者4",H26-H23,0) | DT24: 時間内 | DX24: =IF(Q23="作業者5",H26-H23,0)
CF25: 時間外 | CJ25: =IF(Q23="作業者1",K26-K23,0) | CP25: 時間外 | CT25: =IF(Q23="作業者2",K26-K23,0) | CZ25: 時間外 | DD25: =IF(Q23="作業者3",K26-K23,0) | DJ25: 時間外 | DN25: =IF(Q23="作業者4",K26-K23,0) | DT25: 時間外 | DX25: =IF(Q23="作業者5",K26-K23,0)
CF26: 休日 | CJ26: =IF(Q23="作業者1",N26-N23,0) | CP26: 休日 | CT26: =IF(Q23="作業者2",N26-N23,0) | CZ26: 休日 | DD26: =IF(Q23="作業者3",N26-N23,0) | DJ26: 休日 | DN26: =IF(Q23="作業者4",N26-N23,0) | DT26: 休日 | DX26: =IF(Q23="作業者5",N26-N23,0)
CF27: 移動 | CJ27: =IF(Q27="作業者1",E30-E27,0) | CP27: 移動 | CT27: =IF(Q27="作業者2",E30-E27,0) | CZ27: 移動 | DD27: =IF(Q27="作業者3",E30-E27,0) | DJ27: 移動 | DN27: =IF(Q27="作業者4",E30-E27,0) | DT27: 移動 | DX27: =IF(Q27="作業者5",E30-E27,0)
F28: ～ | I28: ～ | L28: ～ | O28: ～ | CF28: 時間内 | CJ28: =IF(Q27="作業者1",H30-H27,0) | CP28: 時間内 | CT28: =IF(Q27="作業者2",H30-H27,0) | CZ28: 時間内 | DD28: =IF(Q27="作業者3",H30-H27,0) | DJ28: 時間内 | DN28: =IF(Q27="作業者4",H30-H27,0) | DT28: 時間内 | DX28: =IF(Q27="作業者5",H30-H27,0)
CF29: 時間外 | CJ29: =IF(Q27="作業者1",K30-K27,0) | CP29: 時間外 | CT29: =IF(Q27="作業者2",K30-K27,0) | CZ29: 時間外 | DD29: =IF(Q27="作業者3",K30-K27,0) | DJ29: 時間外 | DN29: =IF(Q27="作業者4",K30-K27,0) | DT29: 時間外 | DX29: =IF(Q27="作業者5",K30-K27,0)
CF30: 休日 | CJ30: =IF(Q27="作業者1",N30-N27,0) | CP30: 休日 | CT30: =IF(Q27="作業者2",N30-N27,0) | CZ30: 休日 | DD30: =IF(Q27="作業者3",N30-N27,0) | DJ30: 休日 | DN30: =IF(Q27="作業者4",N30-N27,0) | DT30: 休日 | DX30: =IF(Q27="作業者5",N30-N27,0)
CF31: 移動 | CJ31: =IF(Q31="作業者1",E34-E31,0) | CP31: 移動 | CT31: =IF(Q31="作業者2",E34-E31,0) | CZ31: 移動 | DD31: =IF(Q31="作業者3",E34-E31,0) | DJ31: 移動 | DN31: =IF(Q31="作業者4",E34-E31,0) | DT31: 移動 | DX31: =IF(Q31="作業者5",E34-E31,0)
F32: ～ | I32: ～ | L32: ～ | O32: ～ | CF32: 時間内 | CJ32: =IF(Q31="作業者1",H34-H31,0) | CP32: 時間内 | CT32: =IF(Q31="作業者2",H34-H31,0) | CZ32: 時間内 | DD32: =IF(Q31="作業者3",H34-H31,0) | DJ32: 時間内 | DN32: =IF(Q31="作業者4",H34-H31,0) | DT32: 時間内 | DX32: =IF(Q31="作業者5",H34-H31,0)
CF33: 時間外 | CJ33: =IF(Q31="作業者1",K34-K31,0) | CP33: 時間外 | CT33: =IF(Q31="作業者2",K34-K31,0) | CZ33: 時間外 | DD33: =IF(Q31="作業者3",K34-K31,0) | DJ33: 時間外 | DN33: =IF(Q31="作業者4",K34-K31,0) | DT33: 時間外 | DX33: =IF(Q31="作業者5",K34-K31,0)
CF34: 休日 | CJ34: =IF(Q31="作業者1",N34-N31,0) | CP34: 休日 | CT34: =IF(Q31="作業者2",N34-N31,0) | CZ34: 休日 | DD34: =IF(Q31="作業者3",N34-N31,0) | DJ34: 休日 | DN34: =IF(Q31="作業者4",N34-N31,0) | DT34: 休日 | DX34: =IF(Q31="作業者5",N34-N31,0)
CF35: 移動 | CJ35: =IF(Q35="作業者1",E38-E35,0) | CP35: 移動 | CT35: =IF(Q35="作業者2",E38-E35,0) | CZ35: 移動 | DD35: =IF(Q35="作業者3",E38-E35,0) | DJ35: 移動 | DN35: =IF(Q35="作業者4",E38-E35,0) | DT35: 移動 | DX35: =IF(Q35="作業者5",E38-E35,0)
F36: ～ | I36: ～ | L36: ～ | O36: ～ | CF36: 時間内 | CJ36: =IF(Q35="作業者1",H38-H35,0) | CP36: 時間内 | CT36: =IF(Q35="作業者2",H38-H35,0) | CZ36: 時間内 | DD36: =IF(Q35="作業者3",H38-H35,0) | DJ36: 時間内 | DN36: =IF(Q35="作業者4",H38-H35,0) | DT36: 時間内 | DX36: =IF(Q35="作業者5",H38-H35,0)
CF37: 時間外 | CJ37: =IF(Q35="作業者1",K38-K35,0) | CP37: 時間外 | CT37: =IF(Q35="作業者2",K38-K35,0) | CZ37: 時間外 | DD37: =IF(Q35="作業者3",K38-K35,0) | DJ37: 時間外 | DN37: =IF(Q35="作業者4",K38-K35,0) | DT37: 時間外 | DX37: =IF(Q35="作業者5",K38-K35,0)
CF38: 休日 | CJ38: =IF(Q35="作業者1",N38-N35,0) | CP38: 休日 | CT38: =IF(Q35="作業者2",N38-N35,0) | CZ38: 休日 | DD38: =IF(Q35="作業者3",N38-N35,0) | DJ38: 休日 | DN38: =IF(Q35="作業者4",N38-N35,0) | DT38: 休日 | DX38: =IF(Q35="作業者5",N38-N35,0)
CF39: 移動 | CJ39: =IF(Q39="作業者1",E42-E39,0) | CP39: 移動 | CT39: =IF(Q39="作業者2",E42-E39,0) | CZ39: 移動 | DD39: =IF(Q39="作業者3",E42-E39,0) | DJ39: 移動 | DN39: =IF(Q39="作業者4",E42-E39,0) | DT39: 移動 | DX39: =IF(Q39="作業者5",E42-E39,0)
F40: ～ | I40: ～ | L40: ～ | O40: ～ | CF40: 時間内 | CJ40: =IF(Q39="作業者1",H42-H39,0) | CP40: 時間内 | CT40: =IF(Q39="作業者2",H42-H39,0) | CZ40: 時間内 | DD40: =IF(Q39="作業者3",H42-H39,0) | DJ40: 時間内 | DN40: =IF(Q39="作業者4",H42-H39,0) | DT40: 時間内 | DX40: =IF(Q39="作業者5",H42-H39,0)
CF41: 時間外 | CJ41: =IF(Q39="作業者1",K42-K39,0) | CP41: 時間外 | CT41: =IF(Q39="作業者2",K42-K39,0) | CZ41: 時間外 | DD41: =IF(Q39="作業者3",K42-K39,0) | DJ41: 時間外 | DN41: =IF(Q39="作業者4",K42-K39,0) | DT41: 時間外 | DX41: =IF(Q39="作業者5",K42-K39,0)
CF42: 休日 | CJ42: =IF(Q39="作業者1",N42-N39,0) | CP42: 休日 | CT42: =IF(Q39="作業者2",N42-N39,0) | CZ42: 休日 | DD42: =IF(Q39="作業者3",N42-N39,0) | DJ42: 休日 | DN42: =IF(Q39="作業者4",N42-N39,0) | DT42: 休日 | DX42: =IF(Q39="作業者5",N42-N39,0)
CF43: 移動 | CJ43: =IF(Q43="作業者1",E46-E43,0) | CP43: 移動 | CT43: =IF(Q43="作業者2",E46-E43,0) | CZ43: 移動 | DD43: =IF(Q43="作業者3",E46-E43,0) | DJ43: 移動 | DN43: =IF(Q43="作業者4",E46-E43,0) | DT43: 移動 | DX43: =IF(Q43="作業者5",E46-E43,0)
F44: ～ | I44: ～ | L44: ～ | O44: ～ | CF44: 時間内 | CJ44: =IF(Q43="作業者1",H46-H43,0) | CP44: 時間内 | CT44: =IF(Q43="作業者2",H46-H43,0) | CZ44: 時間内 | DD44: =IF(Q43="作業者3",H46-H43,0) | DJ44: 時間内 | DN44: =IF(Q43="作業者4",H46-H43,0) | DT44: 時間内 | DX44: =IF(Q43="作業者5",H46-H43,0)
CF45: 時間外 | CJ45: =IF(Q43="作業者1",K46-K43,0) | CP45: 時間外 | CT45: =IF(Q43="作業者2",K46-K43,0) | CZ45: 時間外 | DD45: =IF(Q43="作業者3",K46-K43,0) | DJ45: 時間外 | DN45: =IF(Q43="作業者4",K46-K43,0) | DT45: 時間外 | DX45: =IF(Q43="作業者5",K46-K43,0)
CF46: 休日 | CJ46: =IF(Q43="作業者1",N46-N43,0) | CP46: 休日 | CT46: =IF(Q43="作業者2",N46-N43,0) | CZ46: 休日 | DD46: =IF(Q43="作業者3",N46-N43,0) | DJ46: 休日 | DN46: =IF(Q43="作業者4",N46-N43,0) | DT46: 休日 | DX46: =IF(Q43="作業者5",N46-N43,0)
CF47: 移動 | CJ47: =IF(Q47="作業者1",E50-E47,0) | CP47: 移動 | CT47: =IF(Q47="作業者2",E50-E47,0) | CZ47: 移動 | DD47: =IF(Q47="作業者3",E50-E47,0) | DJ47: 移動 | DN47: =IF(Q47="作業者4",E50-E47,0) | DT47: 移動 | DX47: =IF(Q47="作業者5",E50-E47,0)
...

Sheet 作業報告書 (2)
B2: 月／日 | E2: 移 動 | H2: 作業内 (平日) | K2: 作業外 (平日) | N2: 休日 | Q2: 作業者 | T2: 場 所 | W2: 作 業 内 容 | CF2: 所要時間 作業者1 | CP2: 所要時間 作業者2 | CZ2: 所要時間 作業者3 | DJ2: 所要時間 作業者4 | DT2: 所要時間 作業者5
CF4: 移動 | CJ4: =IF(Q4="作業者1",E7-E4,0) | CP4: 移動 | CT4: =IF(Q4="作業者2",E7-E4,0) | CZ4: 移動 | DD4: =IF(Q4="作業者3",E7-E4,0) | DJ4: 移動 | DN4: =IF(Q4="作業者4",E7-E4,0) | DT4: 移動 | DX4: =IF(Q4="作業者5",E7-E4,0)
F5: ～ | I5: ～ | L5: ～ | O5: ～ | CF5: 時間内 | CJ5: =IF(Q4="作業者1",H7-H4,0) | CP5: 時間内 | CT5: =IF(Q4="作業者2",H7-H4,0) | CZ5: 時間内 | DD5: =IF(Q4="作業者3",H7-H4,0) | DJ5: 時間内 | DN5: =IF(Q4="作業者4",H7-H4,0) | DT5: 時間内 | DX5: =IF(Q4="作業者5",H7-H4,0)
CF6: 時間外 | CJ6: =IF(Q4="作業者1",K7-K4,0) | CP6: 時間外 | CT6: =IF(Q4="作業者2",K7-K4,0) | CZ6: 時間外 | DD6: =IF(Q4="作業者3",K7-K4,0) | DJ6: 時間外 | DN6: =IF(Q4="作業者4",K7-K4,0) | DT6: 時間外 | DX6: =IF(Q4="作業者5",K7-K4,0)
CF7: 休日 | CJ7: =IF(Q4="作業者1",N7-N4,0) | CP7: 休日 | CT7: =IF(Q4="作業者2",N7-N4,0) | CZ7: 休日 | DD7: =IF(Q4="作業者3",N7-N4,0) | DJ7: 休日 | DN7: =IF(Q4="作業者4",N7-N4,0) | DT7: 休日 | DX7: =IF(Q4="作業者5",N7-N4,0)
CF8: 移動 | CJ8: =IF(Q8="作業者1",E11-E8,0) | CP8: 移動 | CT8: =IF(Q8="作業者2",E11-E8,0) | CZ8: 移動 | DD8: =IF(Q8="作業者3",E11-E8,0) | DJ8: 移動 | DN8: =IF(Q8="作業者4",E11-E8,0) | DT8: 移動 | DX8: =IF(Q8="作業者5",E11-E8,0)
F9: ～ | I9: ～ | L9: ～ | O9: ～ | CF9: 時間内 | CJ9: =IF(Q8="作業者1",H11-H8,0) | CP9: 時間内 | CT9: =IF(Q8="作業者2",H11-H8,0) | CZ9: 時間内 | DD9: =IF(Q8="作業者3",H11-H8,0) | DJ9: 時間内 | DN9: =IF(Q8="作業者4",H11-H8,0) | DT9: 時間内 | DX9: =IF(Q8="作業者5",H11-H8,0)
CF10: 時間外 | CJ10: =IF(Q8="作業者1",K11-K8,0) | CP10: 時間外 | CT10: =IF(Q8="作業者2",K11-K8,0) | CZ10: 時間外 | DD10: =IF(Q8="作業者3",K11-K8,0) | DJ10: 時間外 | DN10: =IF(Q8="作業者4",K11-K8,0) | DT10: 時間外 | DX10: =IF(Q8="作業者5",K11-K8,0)
CF11: 休日 | CJ11: =IF(Q8="作業者1",N11-N8,0) | CP11: 休日 | CT11: =IF(Q8="作業者2",N11-N8,0) | CZ11: 休日 | DD11: =IF(Q8="作業者3",N11-N8,0) | DJ11: 休日 | DN11: =IF(Q8="作業者4",N11-N8,0) | DT11: 休日 | DX11: =IF(Q8="作業者5",N11-N8,0)
CF12: 移動 | CJ12: =IF(Q12="作業者1",E15-E12,0) | CP12: 移動 | CT12: =IF(Q12="作業者2",E15-E12,0) | CZ12: 移動 | DD12: =IF(Q12="作業者3",E15-E12,0) | DJ12: 移動 | DN12: =IF(Q12="作業者4",E15-E12,0) | DT12: 移動 | DX12: =IF(Q12="作業者5",E15-E12,0)
F13: ～ | I13: ～ | L13: ～ | O13: ～ | CF13: 時間内 | CJ13: =IF(Q12="作業者1",H15-H12,0) | CP13: 時間内 | CT13: =IF(Q12="作業者2",H15-H12,0) | CZ13: 時間内 | DD13: =IF(Q12="作業者3",H15-H12,0) | DJ13: 時間内 | DN13: =IF(Q12="作業者4",H15-H12,0) | DT13: 時間内 | DX13: =IF(Q12="作業者5",H15-H12,0)
CF14: 時間外 | CJ14: =IF(Q12="作業者1",K15-K12,0) | CP14: 時間外 | CT14: =IF(Q12="作業者2",K15-K12,0) | CZ14: 時間外 | DD14: =IF(Q12="作業者3",K15-K12,0) | DJ14: 時間外 | DN14: =IF(Q12="作業者4",K15-K12,0) | DT14: 時間外 | DX14: =IF(Q12="作業者5",K15-K12,0)
CF15: 休日 | CJ15: =IF(Q12="作業者1",N15-N12,0) | CP15: 休日 | CT15: =IF(Q12="作業者2",N15-N12,0) | CZ15: 休日 | DD15: =IF(Q12="作業者3",N15-N12,0) | DJ15: 休日 | DN15: =IF(Q12="作業者4",N15-N12,0) | DT15: 休日 | DX15: =IF(Q12="作業者5",N15-N12,0)
CF16: 移動 | CJ16: =IF(Q16="作業者1",E19-E16,0) | CP16: 移動 | CT16: =IF(Q16="作業者2",E19-E16,0) | CZ16: 移動 | DD16: =IF(Q16="作業者3",E19-E16,0) | DJ16: 移動 | DN16: =IF(Q16="作業者4",E19-E16,0) | DT16: 移動 | DX16: =IF(Q16="作業者5",E19-E16,0)
F17: ～ | I17: ～ | L17: ～ | O17: ～ | CF17: 時間内 | CJ17: =IF(Q16="作業者1",H19-H16,0) | CP17: 時間内 | CT17: =IF(Q16="作業者2",H19-H16,0) | CZ17: 時間内 | DD17: =IF(Q16="作業者3",H19-H16,0) | DJ17: 時間内 | DN17: =IF(Q16="作業者4",H19-H16,0) | DT17: 時間内 | DX17: =IF(Q16="作業者5",H19-H16,0)
CF18: 時間外 | CJ18: =IF(Q16="作業者1",K19-K16,0) | CP18: 時間外 | CT18: =IF(Q16="作業者2",K19-K16,0) | CZ18: 時間外 | DD18: =IF(Q16="作業者3",K19-K16,0) | DJ18: 時間外 | DN18: =IF(Q16="作業者4",K19-K16,0) | DT18: 時間外 | DX18: =IF(Q16="作業者5",K19-K16,0)
CF19: 休日 | CJ19: =IF(Q16="作業者1",N19-N16,0) | CP19: 休日 | CT19: =IF(Q16="作業者2",N19-N16,0) | CZ19: 休日 | DD19: =IF(Q16="作業者3",N19-N16,0) | DJ19: 休日 | DN19: =IF(Q16="作業者4",N19-N16,0) | DT19: 休日 | DX19: =IF(Q16="作業者5",N19-N16,0)
CF20: 移動 | CJ20: =IF(Q20="作業者1",E23-E20,0) | CP20: 移動 | CT20: =IF(Q20="作業者2",E23-E20,0) | CZ20: 移動 | DD20: =IF(Q20="作業者3",E23-E20,0) | DJ20: 移動 | DN20: =IF(Q20="作業者4",E23-E20,0) | DT20: 移動 | DX20: =IF(Q20="作業者5",E23-E20,0)
F21: ～ | I21: ～ | L21: ～ | O21: ～ | CF21: 時間内 | CJ21: =IF(Q20="作業者1",H23-H20,0) | CP21: 時間内 | CT21: =IF(Q20="作業者2",H23-H20,0) | CZ21: 時間内 | DD21: =IF(Q20="作業者3",H23-H20,0) | DJ21: 時間内 | DN21: =IF(Q20="作業者4",H23-H20,0) | DT21: 時間内 | DX21: =IF(Q20="作業者5",H23-H20,0)
CF22: 時間外 | CJ22: =IF(Q20="作業者1",K23-K20,0) | CP22: 時間外 | CT22: =IF(Q20="作業者2",K23-K20,0) | CZ22: 時間外 | DD22: =IF(Q20="作業者3",K23-K20,0) | DJ22: 時間外 | DN22: =IF(Q20="作業者4",K23-K20,0) | DT22: 時間外 | DX22: =IF(Q20="作業者5",K23-K20,0)
CF23: 休日 | CJ23: =IF(Q20="作業者1",N23-N20,0) | CP23: 休日 | CT23: =IF(Q20="作業者2",N23-N20,0) | CZ23: 休日 | DD23: =IF(Q20="作業者3",N23-N20,0) | DJ23: 休日 | DN23: =IF(Q20="作業者4",N23-N20,0) | DT23: 休日 | DX23: =IF(Q20="作業者5",N23-N20,0)
CF24: 移動 | CJ24: =IF(Q24="作業者1",E27-E24,0) | CP24: 移動 | CT24: =IF(Q24="作業者2",E27-E24,0) | CZ24: 移動 | DD24: =IF(Q24="作業者3",E27-E24,0) | DJ24: 移動 | DN24: =IF(Q24="作業者4",E27-E24,0) | DT24: 移動 | DX24: =IF(Q24="作業者5",E27-E24,0)
F25: ～ | I25: ～ | L25: ～ | O25: ～ | CF25: 時間内 | CJ25: =IF(Q24="作業者1",H27-H24,0) | CP25: 時間内 | CT25: =IF(Q24="作業者2",H27-H24,0) | CZ25: 時間内 | DD25: =IF(Q24="作業者3",H27-H24,0) | DJ25: 時間内 | DN25: =IF(Q24="作業者4",H27-H24,0) | DT25: 時間内 | DX25: =IF(Q24="作業者5",H27-H24,0)
CF26: 時間外 | CJ26: =IF(Q24="作業者1",K27-K24,0) | CP26: 時間外 | CT26: =IF(Q24="作業者2",K27-K24,0) | CZ26: 時間外 | DD26: =IF(Q24="作業者3",K27-K24,0) | DJ26: 時間外 | DN26: =IF(Q24="作業者4",K27-K24,0) | DT26: 時間外 | DX26: =IF(Q24="作業者5",K27-K24,0)
CF27: 休日 | CJ27: =IF(Q24="作業者1",N27-N24,0) | CP27: 休日 | CT27: =IF(Q24="作業者2",N27-N24,0) | CZ27: 休日 | DD27: =IF(Q24="作業者3",N27-N24,0) | DJ27: 休日 | DN27: =IF(Q24="作業者4",N27-N24,0) | DT27: 休日 | DX27: =IF(Q24="作業者5",N27-N24,0)
CF28: 移動 | CJ28: =IF(Q28="作業者1",E31-E28,0) | CP28: 移動 | CT28: =IF(Q28="作業者2",E31-E28,0) | CZ28: 移動 | DD28: =IF(Q28="作業者3",E31-E28,0) | DJ28: 移動 | DN28: =IF(Q28="作業者4",E31-E28,0) | DT28: 移動 | DX28: =IF(Q28="作業者5",E31-E28,0)
F29: ～ | I29: ～ | L29: ～ | O29: ～ | CF29: 時間内 | CJ29: =IF(Q28="作業者1",H31-H28,0) | CP29: 時間内 | CT29: =IF(Q28="作業者2",H31-H28,0) | CZ29: 時間内 | DD29: =IF(Q28="作業者3",H31-H28,0) | DJ29: 時間内 | DN29: =IF(Q28="作業者4",H31-H28,0) | DT29: 時間内 | DX29: =IF(Q28="作業者5",H31-H28,0)
CF30: 時間外 | CJ30: =IF(Q28="作業者1",K31-K28,0) | CP30: 時間外 | CT30: =IF(Q28="作業者2",K31-K28,0) | CZ30: 時間外 | DD30: =IF(Q28="作業者3",K31-K28,0) | DJ30: 時間外 | DN30: =IF(Q28="作業者4",K31-K28,0) | DT30: 時間外 | DX30: =IF(Q28="作業者5",K31-K28,0)
CF31: 休日 | CJ31: =IF(Q28="作業者1",N31-N28,0) | CP31: 休日 | CT31: =IF(Q28="作業者2",N31-N28,0) | CZ31: 休日 | DD31: =IF(Q28="作業者3",N31-N28,0) | DJ31: 休日 | DN31: =IF(Q28="作業者4",N31-N28,0) | DT31: 休日 | DX31: =IF(Q28="作業者5",N31-N28,0)
CF32: 移動 | CJ32: =IF(Q32="作業者1",E35-E32,0) | CP32: 移動 | CT32: =IF(Q32="作業者2",E35-E32,0) | CZ32: 移動 | DD32: =IF(Q32="作業者3",E35-E32,0) | DJ32: 移動 | DN32: =IF(Q32="作業者4",E35-E32,0) | DT32: 移動 | DX32: =IF(Q32="作業者5",E35-E32,0)
F33: ～ | I33: ～ | L33: ～ | O33: ～ | CF33: 時間内 | CJ33: =IF(Q32="作業者1",H35-H32,0) | CP33: 時間内 | CT33: =IF(Q32="作業者2",H35-H32,0) | CZ33: 時間内 | DD33: =IF(Q32="作業者3",H35-H32,0) | DJ33: 時間内 | DN33: =IF(Q32="作業者4",H35-H32,0) | DT33: 時間内 | DX33: =IF(Q32="作業者5",H35-H32,0)
CF34: 時間外 | CJ34: =IF(Q32="作業者1",K35-K32,0) | CP34: 時間外 | CT34: =IF(Q32="作業者2",K35-K32,0) | CZ34: 時間外 | DD34: =IF(Q32="作業者3",K35-K32,0) | DJ34: 時間外 | DN34: =IF(Q32="作業者4",K35-K32,0) | DT34: 時間外 | DX34: =IF(Q32="作業者5",K35-K32,0)
CF35: 休日 | CJ35: =IF(Q32="作業者1",N35-N32,0) | CP35: 休日 | CT35: =IF(Q32="作業者2",N35-N32,0) | CZ35: 休日 | DD35: =IF(Q32="作業者3",N35-N32,0) | DJ35: 休日 | DN35: =IF(Q32="作業者4",N35-N32,0) | DT35: 休日 | DX35: =IF(Q32="作業者5",N35-N32,0)
CF36: 移動 | CJ36: =IF(Q36="作業者1",E39-E36,0) | CP36: 移動 | CT36: =IF(Q36="作業者2",E39-E36,0) | CZ36: 移動 | DD36: =IF(Q36="作業者3",E39-E36,0) | DJ36: 移動 | DN36: =IF(Q36="作業者4",E39-E36,0) | DT36: 移動 | DX36: =IF(Q36="作業者5",E39-E36,0)
F37: ～ | I37: ～ | L37: ～ | O37: ～ | CF37: 時間内 | CJ37: =IF(Q36="作業者1",H39-H36,0) | CP37: 時間内 | CT37: =IF(Q36="作業者2",H39-H36,0) | CZ37: 時間内 | DD37: =IF(Q36="作業者3",H39-H36,0) | DJ37: 時間内 | DN37: =IF(Q36="作業者4",H39-H36,0) | DT37: 時間内 | DX37: =IF(Q36="作業者5",H39-H36,0)
CF38: 時間外 | CJ38: =IF(Q36="作業者1",K39-K36,0) | CP38: 時間外 | CT38: =IF(Q36="作業者2",K39-K36,0) | CZ38: 時間外 | DD38: =IF(Q36="作業者3",K39-K36,0) | DJ38: 時間外 | DN38: =IF(Q36="作業者4",K39-K36,0) | DT38: 時間外 | DX38: =IF(Q36="作業者5",K39-K36,0)
CF39: 休日 | CJ39: =IF(Q36="作業者1",N39-N36,0) | CP39: 休日 | CT39: =IF(Q36="作業者2",N39-N36,0) | CZ39: 休日 | DD39: =IF(Q36="作業者3",N39-N36,0) | DJ39: 休日 | DN39: =IF(Q36="作業者4",N39-N36,0) | DT39: 休日 | DX39: =IF(Q36="作業者5",N39-N36,0)
CF40: 移動 | CJ40: =IF(Q40="作業者1",E43-E40,0) | CP40: 移動 | CT40: =IF(Q40="作業者2",E43-E40,0) | CZ40: 移動 | DD40: =IF(Q40="作業者3",E43-E40,0) | DJ40: 移動 | DN40: =IF(Q40="作業者4",E43-E40,0) | DT40: 移動 | DX40: =IF(Q40="作業者5",E43-E40,0)
F41: ～ | I41: ～ | L41: ～ | O41: ～ | CF41: 時間内 | CJ41: =IF(Q40="作業者1",H43-H40,0) | CP41: 時間内 | CT41: =IF(Q40="作業者2",H43-H40,0) | CZ41: 時間内 | DD41: =IF(Q40="作業者3",H43-H40,0) | DJ41: 時間内 | DN41: =IF(Q40="作業者4",H43-H40,0) | DT41: 時間内 | DX41: =IF(Q40="作業者5",H43-H40,0)
CF42: 時間外 | CJ42: =IF(Q40="作業者1",K43-K40,0) | CP42: 時間外 | CT42: =IF(Q40="作業者2",K43-K40,0) | CZ42: 時間外 | DD42: =IF(Q40="作業者3",K43-K40,0) | DJ42: 時間外 | DN42: =IF(Q40="作業者4",K43-K40,0) | DT42: 時間外 | DX42: =IF(Q40="作業者5",K43-K40,0)
...

Sheet 作業報告書 (3)
B2: 月／日 | E2: 移 動 | H2: 作業内 (平日) | K2: 作業外 (平日) | N2: 休日 | Q2: 作業者 | T2: 場 所 | W2: 作 業 内 容 | CF2: 所要時間 作業者1 | CP2: 所要時間 作業者2 | CZ2: 所要時間 作業者3 | DJ2: 所要時間 作業者4 | DT2: 所要時間 作業者5
CF4: 移動 | CJ4: =IF(Q4="作業者1",E7-E4,0) | CP4: 移動 | CT4: =IF(Q4="作業者2",E7-E4,0) | CZ4: 移動 | DD4: =IF(Q4="作業者3",E7-E4,0) | DJ4: 移動 | DN4: =IF(Q4="作業者4",E7-E4,0) | DT4: 移動 | DX4: =IF(Q4="作業者5",E7-E4,0)
F5: ～ | I5: ～ | L5: ～ | O5: ～ | CF5: 時間内 | CJ5: =IF(Q4="作業者1",H7-H4,0) | CP5: 時間内 | CT5: =IF(Q4="作業者2",H7-H4,0) | CZ5: 時間内 | DD5: =IF(Q4="作業者3",H7-H4,0) | DJ5: 時間内 | DN5: =IF(Q4="作業者4",H7-H4,0) | DT5: 時間内 | DX5: =IF(Q4="作業者5",H7-H4,0)
CF6: 時間外 | CJ6: =IF(Q4="作業者1",K7-K4,0) | CP6: 時間外 | CT6: =IF(Q4="作業者2",K7-K4,0) | CZ6: 時間外 | DD6: =IF(Q4="作業者3",K7-K4,0) | DJ6: 時間外 | DN6: =IF(Q4="作業者4",K7-K4,0) | DT6: 時間外 | DX6: =IF(Q4="作業者5",K7-K4,0)
CF7: 休日 | CJ7: =IF(Q4="作業者1",N7-N4,0) | CP7: 休日 | CT7: =IF(Q4="作業者2",N7-N4,0) | CZ7: 休日 | DD7: =IF(Q4="作業者3",N7-N4,0) | DJ7: 休日 | DN7: =IF(Q4="作業者4",N7-N4,0) | DT7: 休日 | DX7: =IF(Q4="作業者5",N7-N4,0)
CF8: 移動 | CJ8: =IF(Q8="作業者1",E11-E8,0) | CP8: 移動 | CT8: =IF(Q8="作業者2",E11-E8,0) | CZ8: 移動 | DD8: =IF(Q8="作業者3",E11-E8,0) | DJ8: 移動 | DN8: =IF(Q8="作業者4",E11-E8,0) | DT8: 移動 | DX8: =IF(Q8="作業者5",E11-E8,0)
F9: ～ | I9: ～ | L9: ～ | O9: ～ | CF9: 時間内 | CJ9: =IF(Q8="作業者1",H11-H8,0) | CP9: 時間内 | CT9: =IF(Q8="作業者2",H11-H8,0) | CZ9: 時間内 | DD9: =IF(Q8="作業者3",H11-H8,0) | DJ9: 時間内 | DN9: =IF(Q8="作業者4",H11-H8,0) | DT9: 時間内 | DX9: =IF(Q8="作業者5",H11-H8,0)
CF10: 時間外 | CJ10: =IF(Q8="作業者1",K11-K8,0) | CP10: 時間外 | CT10: =IF(Q8="作業者2",K11-K8,0) | CZ10: 時間外 | DD10: =IF(Q8="作業者3",K11-K8,0) | DJ10: 時間外 | DN10: =IF(Q8="作業者4",K11-K8,0) | DT10: 時間外 | DX10: =IF(Q8="作業者5",K11-K8,0)
CF11: 休日 | CJ11: =IF(Q8="作業者1",N11-N8,0) | CP11: 休日 | CT11: =IF(Q8="作業者2",N11-N8,0) | CZ11: 休日 | DD11: =IF(Q8="作業者3",N11-N8,0) | DJ11: 休日 | DN11: =IF(Q8="作業者4",N11-N8,0) | DT11: 休日 | DX11: =IF(Q8="作業者5",N11-N8,0)
CF12: 移動 | CJ12: =IF(Q12="作業者1",E15-E12,0) | CP12: 移動 | CT12: =IF(Q12="作業者2",E15-E12,0) | CZ12: 移動 | DD12: =IF(Q12="作業者3",E15-E12,0) | DJ12: 移動 | DN12: =IF(Q12="作業者4",E15-E12,0) | DT12: 移動 | DX12: =IF(Q12="作業者5",E15-E12,0)
F13: ～ | I13: ～ | L13: ～ | O13: ～ | CF13: 時間内 | CJ13: =IF(Q12="作業者1",H15-H12,0) | CP13: 時間内 | CT13: =IF(Q12="作業者2",H15-H12,0) | CZ13: 時間内 | DD13: =IF(Q12="作業者3",H15-H12,0) | DJ13: 時間内 | DN13: =IF(Q12="作業者4",H15-H12,0) | DT13: 時間内 | DX13: =IF(Q12="作業者5",H15-H12,0)
CF14: 時間外 | CJ14: =IF(Q12="作業者1",K15-K12,0) | CP14: 時間外 | CT14: =IF(Q12="作業者2",K15-K12,0) | CZ14: 時間外 | DD14: =IF(Q12="作業者3",K15-K12,0) | DJ14: 時間外 | DN14: =IF(Q12="作業者4",K15-K12,0) | DT14: 時間外 | DX14: =IF(Q12="作業者5",K15-K12,0)
CF15: 休日 | CJ15: =IF(Q12="作業者1",N15-N12,0) | CP15: 休日 | CT15: =IF(Q12="作業者2",N15-N12,0) | CZ15: 休日 | DD15: =IF(Q12="作業者3",N15-N12,0) | DJ15: 休日 | DN15: =IF(Q12="作業者4",N15-N12,0) | DT15: 休日 | DX15: =IF(Q12="作業者5",N15-N12,0)
CF16: 移動 | CJ16: =IF(Q16="作業者1",E19-E16,0) | CP16: 移動 | CT16: =IF(Q16="作業者2",E19-E16,0) | CZ16: 移動 | DD16: =IF(Q16="作業者3",E19-E16,0) | DJ16: 移動 | DN16: =IF(Q16="作業者4",E19-E16,0) | DT16: 移動 | DX16: =IF(Q16="作業者5",E19-E16,0)
F17: ～ | I17: ～ | L17: ～ | O17: ～ | CF17: 時間内 | CJ17: =IF(Q16="作業者1",H19-H16,0) | CP17: 時間内 | CT17: =IF(Q16="作業者2",H19-H16,0) | CZ17: 時間内 | DD17: =IF(Q16="作業者3",H19-H16,0) | DJ17: 時間内 | DN17: =IF(Q16="作業者4",H19-H16,0) | DT17: 時間内 | DX17: =IF(Q16="作業者5",H19-H16,0)
CF18: 時間外 | CJ18: =IF(Q16="作業者1",K19-K16,0) | CP18: 時間外 | CT18: =IF(Q16="作業者2",K19-K16,0) | CZ18: 時間外 | DD18: =IF(Q16="作業者3",K19-K16,0) | DJ18: 時間外 | DN18: =IF(Q16="作業者4",K19-K16,0) | DT18: 時間外 | DX18: =IF(Q16="作業者5",K19-K16,0)
CF19: 休日 | CJ19: =IF(Q16="作業者1",N19-N16,0) | CP19: 休日 | CT19: =IF(Q16="作業者2",N19-N16,0) | CZ19: 休日 | DD19: =IF(Q16="作業者3",N19-N16,0) | DJ19: 休日 | DN19: =IF(Q16="作業者4",N19-N16,0) | DT19: 休日 | DX19: =IF(Q16="作業者5",N19-N16,0)
CF20: 移動 | CJ20: =IF(Q20="作業者1",E23-E20,0) | CP20: 移動 | CT20: =IF(Q20="作業者2",E23-E20,0) | CZ20: 移動 | DD20: =IF(Q20="作業者3",E23-E20,0) | DJ20: 移動 | DN20: =IF(Q20="作業者4",E23-E20,0) | DT20: 移動 | DX20: =IF(Q20="作業者5",E23-E20,0)
F21: ～ | I21: ～ | L21: ～ | O21: ～ | CF21: 時間内 | CJ21: =IF(Q20="作業者1",H23-H20,0) | CP21: 時間内 | CT21: =IF(Q20="作業者2",H23-H20,0) | CZ21: 時間内 | DD21: =IF(Q20="作業者3",H23-H20,0) | DJ21: 時間内 | DN21: =IF(Q20="作業者4",H23-H20,0) | DT21: 時間内 | DX21: =IF(Q20="作業者5",H23-H20,0)
CF22: 時間外 | CJ22: =IF(Q20="作業者1",K23-K20,0) | CP22: 時間外 | CT22: =IF(Q20="作業者2",K23-K20,0) | CZ22: 時間外 | DD22: =IF(Q20="作業者3",K23-K20,0) | DJ22: 時間外 | DN22: =IF(Q20="作業者4",K23-K20,0) | DT22: 時間外 | DX22: =IF(Q20="作業者5",K23-K20,0)
CF23: 休日 | CJ23: =IF(Q20="作業者1",N23-N20,0) | CP23: 休日 | CT23: =IF(Q20="作業者2",N23-N20,0) | CZ23: 休日 | DD23: =IF(Q20="作業者3",N23-N20,0) | DJ23: 休日 | DN23: =IF(Q20="作業者4",N23-N20,0) | DT23: 休日 | DX23: =IF(Q20="作業者5",N23-N20,0)
CF24: 移動 | CJ24: =IF(Q24="作業者1",E27-E24,0) | CP24: 移動 | CT24: =IF(Q24="作業者2",E27-E24,0) | CZ24: 移動 | DD24: =IF(Q24="作業者3",E27-E24,0) | DJ24: 移動 | DN24: =IF(Q24="作業者4",E27-E24,0) | DT24: 移動 | DX24: =IF(Q24="作業者5",E27-E24,0)
F25: ～ | I25: ～ | L25: ～ | O25: ～ | CF25: 時間内 | CJ25: =IF(Q24="作業者1",H27-H24,0) | CP25: 時間内 | CT25: =IF(Q24="作業者2",H27-H24,0) | CZ25: 時間内 | DD25: =IF(Q24="作業者3",H27-H24,0) | DJ25: 時間内 | DN25: =IF(Q24="作業者4",H27-H24,0) | DT25: 時間内 | DX25: =IF(Q24="作業者5",H27-H24,0)
CF26: 時間外 | CJ26: =IF(Q24="作業者1",K27-K24,0) | CP26: 時間外 | CT26: =IF(Q24="作業者2",K27-K24,0) | CZ26: 時間外 | DD26: =IF(Q24="作業者3",K27-K24,0) | DJ26: 時間外 | DN26: =IF(Q24="作業者4",K27-K24,0) | DT26: 時間外 | DX26: =IF(Q24="作業者5",K27-K24,0)
CF27: 休日 | CJ27: =IF(Q24="作業者1",N27-N24,0) | CP27: 休日 | CT27: =IF(Q24="作業者2",N27-N24,0) | CZ27: 休日 | DD27: =IF(Q24="作業者3",N27-N24,0) | DJ27: 休日 | DN27: =IF(Q24="作業者4",N27-N24,0) | DT27: 休日 | DX27: =IF(Q24="作業者5",N27-N24,0)
CF28: 移動 | CJ28: =IF(Q28="作業者1",E31-E28,0) | CP28: 移動 | CT28: =IF(Q28="作業者2",E31-E28,0) | CZ28: 移動 | DD28: =IF(Q28="作業者3",E31-E28,0) | DJ28: 移動 | DN28: =IF(Q28="作業者4",E31-E28,0) | DT28: 移動 | DX28: =IF(Q28="作業者5",E31-E28,0)
F29: ～ | I29: ～ | L29: ～ | O29: ～ | CF29: 時間内 | CJ29: =IF(Q28="作業者1",H31-H28,0) | CP29: 時間内 | CT29: =IF(Q28="作業者2",H31-H28,0) | CZ29: 時間内 | DD29: =IF(Q28="作業者3",H31-H28,0) | DJ29: 時間内 | DN29: =IF(Q28="作業者4",H31-H28,0) | DT29: 時間内 | DX29: =IF(Q28="作業者5",H31-H28,0)
CF30: 時間外 | CJ30: =IF(Q28="作業者1",K31-K28,0) | CP30: 時間外 | CT30: =IF(Q28="作業者2",K31-K28,0) | CZ30: 時間外 | DD30: =IF(Q28="作業者3",K31-K28,0) | DJ30: 時間外 | DN30: =IF(Q28="作業者4",K31-K28,0) | DT30: 時間外 | DX30: =IF(Q28="作業者5",K31-K28,0)
CF31: 休日 | CJ31: =IF(Q28="作業者1",N31-N28,0) | CP31: 休日 | CT31: =IF(Q28="作業者2",N31-N28,0) | CZ31: 休日 | DD31: =IF(Q28="作業者3",N31-N28,0) | DJ31: 休日 | DN31: =IF(Q28="作業者4",N31-N28,0) | DT31: 休日 | DX31: =IF(Q28="作業者5",N31-N28,0)
CF32: 移動 | CJ32: =IF(Q32="作業者1",E35-E32,0) | CP32: 移動 | CT32: =IF(Q32="作業者2",E35-E32,0) | CZ32: 移動 | DD32: =IF(Q32="作業者3",E35-E32,0) | DJ32: 移動 | DN32: =IF(Q32="作業者4",E35-E32,0) | DT32: 移動 | DX32: =IF(Q32="作業者5",E35-E32,0)
F33: ～ | I33: ～ | L33: ～ | O33: ～ | CF33: 時間内 | CJ33: =IF(Q32="作業者1",H35-H32,0) | CP33: 時間内 | CT33: =IF(Q32="作業者2",H35-H32,0) | CZ33: 時間内 | DD33: =IF(Q32="作業者3",H35-H32,0) | DJ33: 時間内 | DN33: =IF(Q32="作業者4",H35-H32,0) | DT33: 時間内 | DX33: =IF(Q32="作業者5",H35-H32,0)
CF34: 時間外 | CJ34: =IF(Q32="作業者1",K35-K32,0) | CP34: 時間外 | CT34: =IF(Q32="作業者2",K35-K32,0) | CZ34: 時間外 | DD34: =IF(Q32="作業者3",K35-K32,0) | DJ34: 時間外 | DN34: =IF(Q32="作業者4",K35-K32,0) | DT34: 時間外 | DX34: =IF(Q32="作業者5",K35-K32,0)
CF35: 休日 | CJ35: =IF(Q32="作業者1",N35-N32,0) | CP35: 休日 | CT35: =IF(Q32="作業者2",N35-N32,0) | CZ35: 休日 | DD35: =IF(Q32="作業者3",N35-N32,0) | DJ35: 休日 | DN35: =IF(Q32="作業者4",N35-N32,0) | DT35: 休日 | DX35: =IF(Q32="作業者5",N35-N32,0)
CF36: 移動 | CJ36: =IF(Q36="作業者1",E39-E36,0) | CP36: 移動 | CT36: =IF(Q36="作業者2",E39-E36,0) | CZ36: 移動 | DD36: =IF(Q36="作業者3",E39-E36,0) | DJ36: 移動 | DN36: =IF(Q36="作業者4",E39-E36,0) | DT36: 移動 | DX36: =IF(Q36="作業者5",E39-E36,0)
F37: ～ | I37: ～ | L37: ～ | O37: ～ | CF37: 時間内 | CJ37: =IF(Q36="作業者1",H39-H36,0) | CP37: 時間内 | CT37: =IF(Q36="作業者2",H39-H36,0) | CZ37: 時間内 | DD37: =IF(Q36="作業者3",H39-H36,0) | DJ37: 時間内 | DN37: =IF(Q36="作業者4",H39-H36,0) | DT37: 時間内 | DX37: =IF(Q36="作業者5",H39-H36,0)
CF38: 時間外 | CJ38: =IF(Q36="作業者1",K39-K36,0) | CP38: 時間外 | CT38: =IF(Q36="作業者2",K39-K36,0) | CZ38: 時間外 | DD38: =IF(Q36="作業者3",K39-K36,0) | DJ38: 時間外 | DN38: =IF(Q36="作業者4",K39-K36,0) | DT38: 時間外 | DX38: =IF(Q36="作業者5",K39-K36,0)
CF39: 休日 | CJ39: =IF(Q36="作業者1",N39-N36,0) | CP39: 休日 | CT39: =IF(Q36="作業者2",N39-N36,0) | CZ39: 休日 | DD39: =IF(Q36="作業者3",N39-N36,0) | DJ39: 休日 | DN39: =IF(Q36="作業者4",N39-N36,0) | DT39: 休日 | DX39: =IF(Q36="作業者5",N39-N36,0)
CF40: 移動 | CJ40: =IF(Q40="作業者1",E43-E40,0) | CP40: 移動 | CT40: =IF(Q40="作業者2",E43-E40,0) | CZ40: 移動 | DD40: =IF(Q40="作業者3",E43-E40,0) | DJ40: 移動 | DN40: =IF(Q40="作業者4",E43-E40,0) | DT40: 移動 | DX40: =IF(Q40="作業者5",E43-E40,0)
F41: ～ | I41: ～ | L41: ～ | O41: ～ | CF41: 時間内 | CJ41: =IF(Q40="作業者1",H43-H40,0) | CP41: 時間内 | CT41: =IF(Q40="作業者2",H43-H40,0) | CZ41: 時間内 | DD41: =IF(Q40="作業者3",H43-H40,0) | DJ41: 時間内 | DN41: =IF(Q40="作業者4",H43-H40,0) | DT41: 時間内 | DX41: =IF(Q40="作業者5",H43-H40,0)
CF42: 時間外 | CJ42: =IF(Q40="作業者1",K43-K40,0) | CP42: 時間外 | CT42: =IF(Q40="作業者2",K43-K40,0) | CZ42: 時間外 | DD42: =IF(Q40="作業者3",K43-K40,0) | DJ42: 時間外 | DN42: =IF(Q40="作業者4",K43-K40,0) | DT42: 時間外 | DX42: =IF(Q40="作業者5",K43-K40,0)
...

Sheet 作業報告書 (4)
B2: 月／日 | E2: 移 動 | H2: 作業内 (平日) | K2: 作業外 (平日) | N2: 休日 | Q2: 作業者 | T2: 場 所 | W2: 作 業 内 容 | CF2: 所要時間 作業者1 | CP2: 所要時間 作業者2 | CZ2: 所要時間 作業者3 | DJ2: 所要時間 作業者4 | DT2: 所要時間 作業者5
CF4: 移動 | CJ4: =IF(Q4="作業者1",E7-E4,0) | CP4: 移動 | CT4: =IF(Q4="作業者2",E7-E4,0) | CZ4: 移動 | DD4: =IF(Q4="作業者3",E7-E4,0) | DJ4: 移動 | DN4: =IF(Q4="作業者4",E7-E4,0) | DT4: 移動 | DX4: =IF(Q4="作業者5",E7-E4,0)
F5: ～ | I5: ～ | L5: ～ | O5: ～ | CF5: 時間内 | CJ5: =IF(Q4="作業者1",H7-H4,0) | CP5: 時間内 | CT5: =IF(Q4="作業者2",H7-H4,0) | CZ5: 時間内 | DD5: =IF(Q4="作業者3",H7-H4,0) | DJ5: 時間内 | DN5: =IF(Q4="作業者4",H7-H4,0) | DT5: 時間内 | DX5: =IF(Q4="作業者5",H7-H4,0)
CF6: 時間外 | CJ6: =IF(Q4="作業者1",K7-K4,0) | CP6: 時間外 | CT6: =IF(Q4="作業者2",K7-K4,0) | CZ6: 時間外 | DD6: =IF(Q4="作業者3",K7-K4,0) | DJ6: 時間外 | DN6: =IF(Q4="作業者4",K7-K4,0) | DT6: 時間外 | DX6: =IF(Q4="作業者5",K7-K4,0)
CF7: 休日 | CJ7: =IF(Q4="作業者1",N7-N4,0) | CP7: 休日 | CT7: =IF(Q4="作業者2",N7-N4,0) | CZ7: 休日 | DD7: =IF(Q4="作業者3",N7-N4,0) | DJ7: 休日 | DN7: =IF(Q4="作業者4",N7-N4,0) | DT7: 休日 | DX7: =IF(Q4="作業者5",N7-N4,0)
CF8: 移動 | CJ8: =IF(Q8="作業者1",E11-E8,0) | CP8: 移動 | CT8: =IF(Q8="作業者2",E11-E8,0) | CZ8: 移動 | DD8: =IF(Q8="作業者3",E11-E8,0) | DJ8: 移動 | DN8: =IF(Q8="作業者4",E11-E8,0) | DT8: 移動 | DX8: =IF(Q8="作業者5",E11-E8,0)
F9: ～ | I9: ～ | L9: ～ | O9: ～ | CF9: 時間内 | CJ9: =IF(Q8="作業者1",H11-H8,0) | CP9: 時間内 | CT9: =IF(Q8="作業者2",H11-H8,0) | CZ9: 時間内 | DD9: =IF(Q8="作業者3",H11-H8,0) | DJ9: 時間内 | DN9: =IF(Q8="作業者4",H11-H8,0) | DT9: 時間内 | DX9: =IF(Q8="作業者5",H11-H8,0)
CF10: 時間外 | CJ10: =IF(Q8="作業者1",K11-K8,0) | CP10: 時間外 | CT10: =IF(Q8="作業者2",K11-K8,0) | CZ10: 時間外 | DD10: =IF(Q8="作業者3",K11-K8,0) | DJ10: 時間外 | DN10: =IF(Q8="作業者4",K11-K8,0) | DT10: 時間外 | DX10: =IF(Q8="作業者5",K11-K8,0)
CF11: 休日 | CJ11: =IF(Q8="作業者1",N11-N8,0) | CP11: 休日 | CT11: =IF(Q8="作業者2",N11-N8,0) | CZ11: 休日 | DD11: =IF(Q8="作業者3",N11-N8,0) | DJ11: 休日 | DN11: =IF(Q8="作業者4",N11-N8,0) | DT11: 休日 | DX11: =IF(Q8="作業者5",N11-N8,0)
CF12: 移動 | CJ12: =IF(Q12="作業者1",E15-E12,0) | CP12: 移動 | CT12: =IF(Q12="作業者2",E15-E12,0) | CZ12: 移動 | DD12: =IF(Q12="作業者3",E15-E12,0) | DJ12: 移動 | DN12: =IF(Q12="作業者4",E15-E12,0) | DT12: 移動 | DX12: =IF(Q12="作業者5",E15-E12,0)
F13: ～ | I13: ～ | L13: ～ | O13: ～ | CF13: 時間内 | CJ13: =IF(Q12="作業者1",H15-H12,0) | CP13: 時間内 | CT13: =IF(Q12="作業者2",H15-H12,0) | CZ13: 時間内 | DD13: =IF(Q12="作業者3",H15-H12,0) | DJ13: 時間内 | DN13: =IF(Q12="作業者4",H15-H12,0) | DT13: 時間内 | DX13: =IF(Q12="作業者5",H15-H12,0)
CF14: 時間外 | CJ14: =IF(Q12="作業者1",K15-K12,0) | CP14: 時間外 | CT14: =IF(Q12="作業者2",K15-K12,0) | CZ14: 時間外 | DD14: =IF(Q12="作業者3",K15-K12,0) | DJ14: 時間外 | DN14: =IF(Q12="作業者4",K15-K12,0) | DT14: 時間外 | DX14: =IF(Q12="作業者5",K15-K12,0)
CF15: 休日 | CJ15: =IF(Q12="作業者1",N15-N12,0) | CP15: 休日 | CT15: =IF(Q12="作業者2",N15-N12,0) | CZ15: 休日 | DD15: =IF(Q12="作業者3",N15-N12,0) | DJ15: 休日 | DN15: =IF(Q12="作業者4",N15-N12,0) | DT15: 休日 | DX15: =IF(Q12="作業者5",N15-N12,0)
CF16: 移動 | CJ16: =IF(Q16="作業者1",E19-E16,0) | CP16: 移動 | CT16: =IF(Q16="作業者2",E19-E16,0) | CZ16: 移動 | DD16: =IF(Q16="作業者3",E19-E16,0) | DJ16: 移動 | DN16: =IF(Q16="作業者4",E19-E16,0) | DT16: 移動 | DX16: =IF(Q16="作業者5",E19-E16,0)
F17: ～ | I17: ～ | L17: ～ | O17: ～ | CF17: 時間内 | CJ17: =IF(Q16="作業者1",H19-H16,0) | CP17: 時間内 | CT17: =IF(Q16="作業者2",H19-H16,0) | CZ17: 時間内 | DD17: =IF(Q16="作業者3",H19-H16,0) | DJ17: 時間内 | DN17: =IF(Q16="作業者4",H19-H16,0) | DT17: 時間内 | DX17: =IF(Q16="作業者5",H19-H16,0)
CF18: 時間外 | CJ18: =IF(Q16="作業者1",K19-K16,0) | CP18: 時間外 | CT18: =IF(Q16="作業者2",K19-K16,0) | CZ18: 時間外 | DD18: =IF(Q16="作業者3",K19-K16,0) | DJ18: 時間外 | DN18: =IF(Q16="作業者4",K19-K16,0) | DT18: 時間外 | DX18: =IF(Q16="作業者5",K19-K16,0)
CF19: 休日 | CJ19: =IF(Q16="作業者1",N19-N16,0) | CP19: 休日 | CT19: =IF(Q16="作業者2",N19-N16,0) | CZ19: 休日 | DD19: =IF(Q16="作業者3",N19-N16,0) | DJ19: 休日 | DN19: =IF(Q16="作業者4",N19-N16,0) | DT19: 休日 | DX19: =IF(Q16="作業者5",N19-N16,0)
CF20: 移動 | CJ20: =IF(Q20="作業者1",E23-E20,0) | CP20: 移動 | CT20: =IF(Q20="作業者2",E23-E20,0) | CZ20: 移動 | DD20: =IF(Q20="作業者3",E23-E20,0) | DJ20: 移動 | DN20: =IF(Q20="作業者4",E23-E20,0) | DT20: 移動 | DX20: =IF(Q20="作業者5",E23-E20,0)
F21: ～ | I21: ～ | L21: ～ | O21: ～ | CF21: 時間内 | CJ21: =IF(Q20="作業者1",H23-H20,0) | CP21: 時間内 | CT21: =IF(Q20="作業者2",H23-H20,0) | CZ21: 時間内 | DD21: =IF(Q20="作業者3",H23-H20,0) | DJ21: 時間内 | DN21: =IF(Q20="作業者4",H23-H20,0) | DT21: 時間内 | DX21: =IF(Q20="作業者5",H23-H20,0)
CF22: 時間外 | CJ22: =IF(Q20="作業者1",K23-K20,0) | CP22: 時間外 | CT22: =IF(Q20="作業者2",K23-K20,0) | CZ22: 時間外 | DD22: =IF(Q20="作業者3",K23-K20,0) | DJ22: 時間外 | DN22: =IF(Q20="作業者4",K23-K20,0) | DT22: 時間外 | DX22: =IF(Q20="作業者5",K23-K20,0)
CF23: 休日 | CJ23: =IF(Q20="作業者1",N23-N20,0) | CP23: 休日 | CT23: =IF(Q20="作業者2",N23-N20,0) | CZ23: 休日 | DD23: =IF(Q20="作業者3",N23-N20,0) | DJ23: 休日 | DN23: =IF(Q20="作業者4",N23-N20,0) | DT23: 休日 | DX23: =IF(Q20="作業者5",N23-N20,0)
CF24: 移動 | CJ24: =IF(Q24="作業者1",E27-E24,0) | CP24: 移動 | CT24: =IF(Q24="作業者2",E27-E24,0) | CZ24: 移動 | DD24: =IF(Q24="作業者3",E27-E24,0) | DJ24: 移動 | DN24: =IF(Q24="作業者4",E27-E24,0) | DT24: 移動 | DX24: =IF(Q24="作業者5",E27-E24,0)
F25: ～ | I25: ～ | L25: ～ | O25: ～ | CF25: 時間内 | CJ25: =IF(Q24="作業者1",H27-H24,0) | CP25: 時間内 | CT25: =IF(Q24="作業者2",H27-H24,0) | CZ25: 時間内 | DD25: =IF(Q24="作業者3",H27-H24,0) | DJ25: 時間内 | DN25: =IF(Q24="作業者4",H27-H24,0) | DT25: 時間内 | DX25: =IF(Q24="作業者5",H27-H24,0)
CF26: 時間外 | CJ26: =IF(Q24="作業者1",K27-K24,0) | CP26: 時間外 | CT26: =IF(Q24="作業者2",K27-K24,0) | CZ26: 時間外 | DD26: =IF(Q24="作業者3",K27-K24,0) | DJ26: 時間外 | DN26: =IF(Q24="作業者4",K27-K24,0) | DT26: 時間外 | DX26: =IF(Q24="作業者5",K27-K24,0)
CF27: 休日 | CJ27: =IF(Q24="作業者1",N27-N24,0) | CP27: 休日 | CT27: =IF(Q24="作業者2",N27-N24,0) | CZ27: 休日 | DD27: =IF(Q24="作業者3",N27-N24,0) | DJ27: 休日 | DN27: =IF(Q24="作業者4",N27-N24,0) | DT27: 休日 | DX27: =IF(Q24="作業者5",N27-N24,0)
CF28: 移動 | CJ28: =IF(Q28="作業者1",E31-E28,0) | CP28: 移動 | CT28: =IF(Q28="作業者2",E31-E28,0) | CZ28: 移動 | DD28: =IF(Q28="作業者3",E31-E28,0) | DJ28: 移動 | DN28: =IF(Q28="作業者4",E31-E28,0) | DT28: 移動 | DX28: =IF(Q28="作業者5",E31-E28,0)
F29: ～ | I29: ～ | L29: ～ | O29: ～ | CF29: 時間内 | CJ29: =IF(Q28="作業者1",H31-H28,0) | CP29: 時間内 | CT29: =IF(Q28="作業者2",H31-H28,0) | CZ29: 時間内 | DD29: =IF(Q28="作業者3",H31-H28,0) | DJ29: 時間内 | DN29: =IF(Q28="作業者4",H31-H28,0) | DT29: 時間内 | DX29: =IF(Q28="作業者5",H31-H28,0)
CF30: 時間外 | CJ30: =IF(Q28="作業者1",K31-K28,0) | CP30: 時間外 | CT30: =IF(Q28="作業者2",K31-K28,0) | CZ30: 時間外 | DD30: =IF(Q28="作業者3",K31-K28,0) | DJ30: 時間外 | DN30: =IF(Q28="作業者4",K31-K28,0) | DT30: 時間外 | DX30: =IF(Q28="作業者5",K31-K28,0)
CF31: 休日 | CJ31: =IF(Q28="作業者1",N31-N28,0) | CP31: 休日 | CT31: =IF(Q28="作業者2",N31-N28,0) | CZ31: 休日 | DD31: =IF(Q28="作業者3",N31-N28,0) | DJ31: 休日 | DN31: =IF(Q28="作業者4",N31-N28,0) | DT31: 休日 | DX31: =IF(Q28="作業者5",N31-N28,0)
CF32: 移動 | CJ32: =IF(Q32="作業者1",E35-E32,0) | CP32: 移動 | CT32: =IF(Q32="作業者2",E35-E32,0) | CZ32: 移動 | DD32: =IF(Q32="作業者3",E35-E32,0) | DJ32: 移動 | DN32: =IF(Q32="作業者4",E35-E32,0) | DT32: 移動 | DX32: =IF(Q32="作業者5",E35-E32,0)
F33: ～ | I33: ～ | L33: ～ | O33: ～ | CF33: 時間内 | CJ33: =IF(Q32="作業者1",H35-H32,0) | CP33: 時間内 | CT33: =IF(Q32="作業者2",H35-H32,0) | CZ33: 時間内 | DD33: =IF(Q32="作業者3",H35-H32,0) | DJ33: 時間内 | DN33: =IF(Q32="作業者4",H35-H32,0) | DT33: 時間内 | DX33: =IF(Q32="作業者5",H35-H32,0)
CF34: 時間外 | CJ34: =IF(Q32="作業者1",K35-K32,0) | CP34: 時間外 | CT34: =IF(Q32="作業者2",K35-K32,0) | CZ34: 時間外 | DD34: =IF(Q32="作業者3",K35-K32,0) | DJ34: 時間外 | DN34: =IF(Q32="作業者4",K35-K32,0) | DT34: 時間外 | DX34: =IF(Q32="作業者5",K35-K32,0)
CF35: 休日 | CJ35: =IF(Q32="作業者1",N35-N32,0) | CP35: 休日 | CT35: =IF(Q32="作業者2",N35-N32,0) | CZ35: 休日 | DD35: =IF(Q32="作業者3",N35-N32,0) | DJ35: 休日 | DN35: =IF(Q32="作業者4",N35-N32,0) | DT35: 休日 | DX35: =IF(Q32="作業者5",N35-N32,0)
CF36: 移動 | CJ36: =IF(Q36="作業者1",E39-E36,0) | CP36: 移動 | CT36: =IF(Q36="作業者2",E39-E36,0) | CZ36: 移動 | DD36: =IF(Q36="作業者3",E39-E36,0) | DJ36: 移動 | DN36: =IF(Q36="作業者4",E39-E36,0) | DT36: 移動 | DX36: =IF(Q36="作業者5",E39-E36,0)
F37: ～ | I37: ～ | L37: ～ | O37: ～ | CF37: 時間内 | CJ37: =IF(Q36="作業者1",H39-H36,0) | CP37: 時間内 | CT37: =IF(Q36="作業者2",H39-H36,0) | CZ37: 時間内 | DD37: =IF(Q36="作業者3",H39-H36,0) | DJ37: 時間内 | DN37: =IF(Q36="作業者4",H39-H36,0) | DT37: 時間内 | DX37: =IF(Q36="作業者5",H39-H36,0)
CF38: 時間外 | CJ38: =IF(Q36="作業者1",K39-K36,0) | CP38: 時間外 | CT38: =IF(Q36="作業者2",K39-K36,0) | CZ38: 時間外 | DD38: =IF(Q36="作業者3",K39-K36,0) | DJ38: 時間外 | DN38: =IF(Q36="作業者4",K39-K36,0) | DT38: 時間外 | DX38: =IF(Q36="作業者5",K39-K36,0)
CF39: 休日 | CJ39: =IF(Q36="作業者1",N39-N36,0) | CP39: 休日 | CT39: =IF(Q36="作業者2",N39-N36,0) | CZ39: 休日 | DD39: =IF(Q36="作業者3",N39-N36,0) | DJ39: 休日 | DN39: =IF(Q36="作業者4",N39-N36,0) | DT39: 休日 | DX39: =IF(Q36="作業者5",N39-N36,0)
CF40: 移動 | CJ40: =IF(Q40="作業者1",E43-E40,0) | CP40: 移動 | CT40: =IF(Q40="作業者2",E43-E40,0) | CZ40: 移動 | DD40: =IF(Q40="作業者3",E43-E40,0) | DJ40: 移動 | DN40: =IF(Q40="作業者4",E43-E40,0) | DT40: 移動 | DX40: =IF(Q40="作業者5",E43-E40,0)
F41: ～ | I41: ～ | L41: ～ | O41: ～ | CF41: 時間内 | CJ41: =IF(Q40="作業者1",H43-H40,0) | CP41: 時間内 | CT41: =IF(Q40="作業者2",H43-H40,0) | CZ41: 時間内 | DD41: =IF(Q40="作業者3",H43-H40,0) | DJ41: 時間内 | DN41: =IF(Q40="作業者4",H43-H40,0) | DT41: 時間内 | DX41: =IF(Q40="作業者5",H43-H40,0)
CF42: 時間外 | CJ42: =IF(Q40="作業者1",K43-K40,0) | CP42: 時間外 | CT42: =IF(Q40="作業者2",K43-K40,0) | CZ42: 時間外 | DD42: =IF(Q40="作業者3",K43-K40,0) | DJ42: 時間外 | DN42: =IF(Q40="作業者4",K43-K40,0) | DT42: 時間外 | DX42: =IF(Q40="作業者5",K43-K40,0)
...

Sheet 作業報告書 (5)
B2: 月／日 | E2: 移 動 | H2: 作業内 (平日) | K2: 作業外 (平日) | N2: 休日 | Q2: 作業者 | T2: 場 所 | W2: 作 業 内 容 | CF2: 所要時間 作業者1 | CP2: 所要時間 作業者2 | CZ2: 所要時間 作業者3 | DJ2: 所要時間 作業者4 | DT2: 所要時間 作業者5
CF4: 移動 | CJ4: =IF(Q4="作業者1",E7-E4,0) | CP4: 移動 | CT4: =IF(Q4="作業者2",E7-E4,0) | CZ4: 移動 | DD4: =IF(Q4="作業者3",E7-E4,0) | DJ4: 移動 | DN4: =IF(Q4="作業者4",E7-E4,0) | DT4: 移動 | DX4: =IF(Q4="作業者5",E7-E4,0)
F5: ～ | I5: ～ | L5: ～ | O5: ～ | CF5: 時間内 | CJ5: =IF(Q4="作業者1",H7-H4,0) | CP5: 時間内 | CT5: =IF(Q4="作業者2",H7-H4,0) | CZ5: 時間内 | DD5: =IF(Q4="作業者3",H7-H4,0) | DJ5: 時間内 | DN5: =IF(Q4="作業者4",H7-H4,0) | DT5: 時間内 | DX5: =IF(Q4="作業者5",H7-H4,0)
CF6: 時間外 | CJ6: =IF(Q4="作業者1",K7-K4,0) | CP6: 時間外 | CT6: =IF(Q4="作業者2",K7-K4,0) | CZ6: 時間外 | DD6: =IF(Q4="作業者3",K7-K4,0) | DJ6: 時間外 | DN6: =IF(Q4="作業者4",K7-K4,0) | DT6: 時間外 | DX6: =IF(Q4="作業者5",K7-K4,0)
CF7: 休日 | CJ7: =IF(Q4="作業者1",N7-N4,0) | CP7: 休日 | CT7: =IF(Q4="作業者2",N7-N4,0) | CZ7: 休日 | DD7: =IF(Q4="作業者3",N7-N4,0) | DJ7: 休日 | DN7: =IF(Q4="作業者4",N7-N4,0) | DT7: 休日 | DX7: =IF(Q4="作業者5",N7-N4,0)
CF8: 移動 | CJ8: =IF(Q8="作業者1",E11-E8,0) | CP8: 移動 | CT8: =IF(Q8="作業者2",E11-E8,0) | CZ8: 移動 | DD8: =IF(Q8="作業者3",E11-E8,0) | DJ8: 移動 | DN8: =IF(Q8="作業者4",E11-E8,0) | DT8: 移動 | DX8: =IF(Q8="作業者5",E11-E8,0)
F9: ～ | I9: ～ | L9: ～ | O9: ～ | CF9: 時間内 | CJ9: =IF(Q8="作業者1",H11-H8,0) | CP9: 時間内 | CT9: =IF(Q8="作業者2",H11-H8,0) | CZ9: 時間内 | DD9: =IF(Q8="作業者3",H11-H8,0) | DJ9: 時間内 | DN9: =IF(Q8="作業者4",H11-H8,0) | DT9: 時間内 | DX9: =IF(Q8="作業者5",H11-H8,0)
CF10: 時間外 | CJ10: =IF(Q8="作業者1",K11-K8,0) | CP10: 時間外 | CT10: =IF(Q8="作業者2",K11-K8,0) | CZ10: 時間外 | DD10: =IF(Q8="作業者3",K11-K8,0) | DJ10: 時間外 | DN10: =IF(Q8="作業者4",K11-K8,0) | DT10: 時間外 | DX10: =IF(Q8="作業者5",K11-K8,0)
CF11: 休日 | CJ11: =IF(Q8="作業者1",N11-N8,0) | CP11: 休日 | CT11: =IF(Q8="作業者2",N11-N8,0) | CZ11: 休日 | DD11: =IF(Q8="作業者3",N11-N8,0) | DJ11: 休日 | DN11: =IF(Q8="作業者4",N11-N8,0) | DT11: 休日 | DX11: =IF(Q8="作業者5",N11-N8,0)
CF12: 移動 | CJ12: =IF(Q12="作業者1",E15-E12,0) | CP12: 移動 | CT12: =IF(Q12="作業者2",E15-E12,0) | CZ12: 移動 | DD12: =IF(Q12="作業者3",E15-E12,0) | DJ12: 移動 | DN12: =IF(Q12="作業者4",E15-E12,0) | DT12: 移動 | DX12: =IF(Q12="作業者5",E15-E12,0)
F13: ～ | I13: ～ | L13: ～ | O13: ～ | CF13: 時間内 | CJ13: =IF(Q12="作業者1",H15-H12,0) | CP13: 時間内 | CT13: =IF(Q12="作業者2",H15-H12,0) | CZ13: 時間内 | DD13: =IF(Q12="作業者3",H15-H12,0) | DJ13: 時間内 | DN13: =IF(Q12="作業者4",H15-H12,0) | DT13: 時間内 | DX13: =IF(Q12="作業者5",H15-H12,0)
CF14: 時間外 | CJ14: =IF(Q12="作業者1",K15-K12,0) | CP14: 時間外 | CT14: =IF(Q12="作業者2",K15-K12,0) | CZ14: 時間外 | DD14: =IF(Q12="作業者3",K15-K12,0) | DJ14: 時間外 | DN14: =IF(Q12="作業者4",K15-K12,0) | DT14: 時間外 | DX14: =IF(Q12="作業者5",K15-K12,0)
CF15: 休日 | CJ15: =IF(Q12="作業者1",N15-N12,0) | CP15: 休日 | CT15: =IF(Q12="作業者2",N15-N12,0) | CZ15: 休日 | DD15: =IF(Q12="作業者3",N15-N12,0) | DJ15: 休日 | DN15: =IF(Q12="作業者4",N15-N12,0) | DT15: 休日 | DX15: =IF(Q12="作業者5",N15-N12,0)
CF16: 移動 | CJ16: =IF(Q16="作業者1",E19-E16,0) | CP16: 移動 | CT16: =IF(Q16="作業者2",E19-E16,0) | CZ16: 移動 | DD16: =IF(Q16="作業者3",E19-E16,0) | DJ16: 移動 | DN16: =IF(Q16="作業者4",E19-E16,0) | DT16: 移動 | DX16: =IF(Q16="作業者5",E19-E16,0)
F17: ～ | I17: ～ | L17: ～ | O17: ～ | CF17: 時間内 | CJ17: =IF(Q16="作業者1",H19-H16,0) | CP17: 時間内 | CT17: =IF(Q16="作業者2",H19-H16,0) | CZ17: 時間内 | DD17: =IF(Q16="作業者3",H19-H16,0) | DJ17: 時間内 | DN17: =IF(Q16="作業者4",H19-H16,0) | DT17: 時間内 | DX17: =IF(Q16="作業者5",H19-H16,0)
CF18: 時間外 | CJ18: =IF(Q16="作業者1",K19-K16,0) | CP18: 時間外 | CT18: =IF(Q16="作業者2",K19-K16,0) | CZ18: 時間外 | DD18: =IF(Q16="作業者3",K19-K16,0) | DJ18: 時間外 | DN18: =IF(Q16="作業者4",K19-K16,0) | DT18: 時間外 | DX18: =IF(Q16="作業者5",K19-K16,0)
CF19: 休日 | CJ19: =IF(Q16="作業者1",N19-N16,0) | CP19: 休日 | CT19: =IF(Q16="作業者2",N19-N16,0) | CZ19: 休日 | DD19: =IF(Q16="作業者3",N19-N16,0) | DJ19: 休日 | DN19: =IF(Q16="作業者4",N19-N16,0) | DT19: 休日 | DX19: =IF(Q16="作業者5",N19-N16,0)
CF20: 移動 | CJ20: =IF(Q20="作業者1",E23-E20,0) | CP20: 移動 | CT20: =IF(Q20="作業者2",E23-E20,0) | CZ20: 移動 | DD20: =IF(Q20="作業者3",E23-E20,0) | DJ20: 移動 | DN20: =IF(Q20="作業者4",E23-E20,0) | DT20: 移動 | DX20: =IF(Q20="作業者5",E23-E20,0)
F21: ～ | I21: ～ | L21: ～ | O21: ～ | CF21: 時間内 | CJ21: =IF(Q20="作業者1",H23-H20,0) | CP21: 時間内 | CT21: =IF(Q20="作業者2",H23-H20,0) | CZ21: 時間内 | DD21: =IF(Q20="作業者3",H23-H20,0) | DJ21: 時間内 | DN21: =IF(Q20="作業者4",H23-H20,0) | DT21: 時間内 | DX21: =IF(Q20="作業者5",H23-H20,0)
CF22: 時間外 | CJ22: =IF(Q20="作業者1",K23-K20,0) | CP22: 時間外 | CT22: =IF(Q20="作業者2",K23-K20,0) | CZ22: 時間外 | DD22: =IF(Q20="作業者3",K23-K20,0) | DJ22: 時間外 | DN22: =IF(Q20="作業者4",K23-K20,0) | DT22: 時間外 | DX22: =IF(Q20="作業者5",K23-K20,0)
CF23: 休日 | CJ23: =IF(Q20="作業者1",N23-N20,0) | CP23: 休日 | CT23: =IF(Q20="作業者2",N23-N20,0) | CZ23: 休日 | DD23: =IF(Q20="作業者3",N23-N20,0) | DJ23: 休日 | DN23: =IF(Q20="作業者4",N23-N20,0) | DT23: 休日 | DX23: =IF(Q20="作業者5",N23-N20,0)
CF24: 移動 | CJ24: =IF(Q24="作業者1",E27-E24,0) | CP24: 移動 | CT24: =IF(Q24="作業者2",E27-E24,0) | CZ24: 移動 | DD24: =IF(Q24="作業者3",E27-E24,0) | DJ24: 移動 | DN24: =IF(Q24="作業者4",E27-E24,0) | DT24: 移動 | DX24: =IF(Q24="作業者5",E27-E24,0)
F25: ～ | I25: ～ | L25: ～ | O25: ～ | CF25: 時間内 | CJ25: =IF(Q24="作業者1",H27-H24,0) | CP25: 時間内 | CT25: =IF(Q24="作業者2",H27-H24,0) | CZ25: 時間内 | DD25: =IF(Q24="作業者3",H27-H24,0) | DJ25: 時間内 | DN25: =IF(Q24="作業者4",H27-H24,0) | DT25: 時間内 | DX25: =IF(Q24="作業者5",H27-H24,0)
CF26: 時間外 | CJ26: =IF(Q24="作業者1",K27-K24,0) | CP26: 時間外 | CT26: =IF(Q24="作業者2",K27-K24,0) | CZ26: 時間外 | DD26: =IF(Q24="作業者3",K27-K24,0) | DJ26: 時間外 | DN26: =IF(Q24="作業者4",K27-K24,0) | DT26: 時間外 | DX26: =IF(Q24="作業者5",K27-K24,0)
CF27: 休日 | CJ27: =IF(Q24="作業者1",N27-N24,0) | CP27: 休日 | CT27: =IF(Q24="作業者2",N27-N24,0) | CZ27: 休日 | DD27: =IF(Q24="作業者3",N27-N24,0) | DJ27: 休日 | DN27: =IF(Q24="作業者4",N27-N24,0) | DT27: 休日 | DX27: =IF(Q24="作業者5",N27-N24,0)
CF28: 移動 | CJ28: =IF(Q28="作業者1",E31-E28,0) | CP28: 移動 | CT28: =IF(Q28="作業者2",E31-E28,0) | CZ28: 移動 | DD28: =IF(Q28="作業者3",E31-E28,0) | DJ28: 移動 | DN28: =IF(Q28="作業者4",E31-E28,0) | DT28: 移動 | DX28: =IF(Q28="作業者5",E31-E28,0)
F29: ～ | I29: ～ | L29: ～ | O29: ～ | CF29: 時間内 | CJ29: =IF(Q28="作業者1",H31-H28,0) | CP29: 時間内 | CT29: =IF(Q28="作業者2",H31-H28,0) | CZ29: 時間内 | DD29: =IF(Q28="作業者3",H31-H28,0) | DJ29: 時間内 | DN29: =IF(Q28="作業者4",H31-H28,0) | DT29: 時間内 | DX29: =IF(Q28="作業者5",H31-H28,0)
CF30: 時間外 | CJ30: =IF(Q28="作業者1",K31-K28,0) | CP30: 時間外 | CT30: =IF(Q28="作業者2",K31-K28,0) | CZ30: 時間外 | DD30: =IF(Q28="作業者3",K31-K28,0) | DJ30: 時間外 | DN30: =IF(Q28="作業者4",K31-K28,0) | DT30: 時間外 | DX30: =IF(Q28="作業者5",K31-K28,0)
CF31: 休日 | CJ31: =IF(Q28="作業者1",N31-N28,0) | CP31: 休日 | CT31: =IF(Q28="作業者2",N31-N28,0) | CZ31: 休日 | DD31: =IF(Q28="作業者3",N31-N28,0) | DJ31: 休日 | DN31: =IF(Q28="作業者4",N31-N28,0) | DT31: 休日 | DX31: =IF(Q28="作業者5",N31-N28,0)
CF32: 移動 | CJ32: =IF(Q32="作業者1",E35-E32,0) | CP32: 移動 | CT32: =IF(Q32="作業者2",E35-E32,0) | CZ32: 移動 | DD32: =IF(Q32="作業者3",E35-E32,0) | DJ32: 移動 | DN32: =IF(Q32="作業者4",E35-E32,0) | DT32: 移動 | DX32: =IF(Q32="作業者5",E35-E32,0)
F33: ～ | I33: ～ | L33: ～ | O33: ～ | CF33: 時間内 | CJ33: =IF(Q32="作業者1",H35-H32,0) | CP33: 時間内 | CT33: =IF(Q32="作業者2",H35-H32,0) | CZ33: 時間内 | DD33: =IF(Q32="作業者3",H35-H32,0) | DJ33: 時間内 | DN33: =IF(Q32="作業者4",H35-H32,0) | DT33: 時間内 | DX33: =IF(Q32="作業者5",H35-H32,0)
CF34: 時間外 | CJ34: =IF(Q32="作業者1",K35-K32,0) | CP34: 時間外 | CT34: =IF(Q32="作業者2",K35-K32,0) | CZ34: 時間外 | DD34: =IF(Q32="作業者3",K35-K32,0) | DJ34: 時間外 | DN34: =IF(Q32="作業者4",K35-K32,0) | DT34: 時間外 | DX34: =IF(Q32="作業者5",K35-K32,0)
CF35: 休日 | CJ35: =IF(Q32="作業者1",N35-N32,0) | CP35: 休日 | CT35: =IF(Q32="作業者2",N35-N32,0) | CZ35: 休日 | DD35: =IF(Q32="作業者3",N35-N32,0) | DJ35: 休日 | DN35: =IF(Q32="作業者4",N35-N32,0) | DT35: 休日 | DX35: =IF(Q32="作業者5",N35-N32,0)
CF36: 移動 | CJ36: =IF(Q36="作業者1",E39-E36,0) | CP36: 移動 | CT36: =IF(Q36="作業者2",E39-E36,0) | CZ36: 移動 | DD36: =IF(Q36="作業者3",E39-E36,0) | DJ36: 移動 | DN36: =IF(Q36="作業者4",E39-E36,0) | DT36: 移動 | DX36: =IF(Q36="作業者5",E39-E36,0)
F37: ～ | I37: ～ | L37: ～ | O37: ～ | CF37: 時間内 | CJ37: =IF(Q36="作業者1",H39-H36,0) | CP37: 時間内 | CT37: =IF(Q36="作業者2",H39-H36,0) | CZ37: 時間内 | DD37: =IF(Q36="作業者3",H39-H36,0) | DJ37: 時間内 | DN37: =IF(Q36="作業者4",H39-H36,0) | DT37: 時間内 | DX37: =IF(Q36="作業者5",H39-H36,0)
CF38: 時間外 | CJ38: =IF(Q36="作業者1",K39-K36,0) | CP38: 時間外 | CT38: =IF(Q36="作業者2",K39-K36,0) | CZ38: 時間外 | DD38: =IF(Q36="作業者3",K39-K36,0) | DJ38: 時間外 | DN38: =IF(Q36="作業者4",K39-K36,0) | DT38: 時間外 | DX38: =IF(Q36="作業者5",K39-K36,0)
CF39: 休日 | CJ39: =IF(Q36="作業者1",N39-N36,0) | CP39: 休日 | CT39: =IF(Q36="作業者2",N39-N36,0) | CZ39: 休日 | DD39: =IF(Q36="作業者3",N39-N36,0) | DJ39: 休日 | DN39: =IF(Q36="作業者4",N39-N36,0) | DT39: 休日 | DX39: =IF(Q36="作業者5",N39-N36,0)
CF40: 移動 | CJ40: =IF(Q40="作業者1",E43-E40,0) | CP40: 移動 | CT40: =IF(Q40="作業者2",E43-E40,0) | CZ40: 移動 | DD40: =IF(Q40="作業者3",E43-E40,0) | DJ40: 移動 | DN40: =IF(Q40="作業者4",E43-E40,0) | DT40: 移動 | DX40: =IF(Q40="作業者5",E43-E40,0)
F41: ～ | I41: ～ | L41: ～ | O41: ～ | CF41: 時間内 | CJ41: =IF(Q40="作業者1",H43-H40,0) | CP41: 時間内 | CT41: =IF(Q40="作業者2",H43-H40,0) | CZ41: 時間内 | DD41: =IF(Q40="作業者3",H43-H40,0) | DJ41: 時間内 | DN41: =IF(Q40="作業者4",H43-H40,0) | DT41: 時間内 | DX41: =IF(Q40="作業者5",H43-H40,0)
CF42: 時間外 | CJ42: =IF(Q40="作業者1",K43-K40,0) | CP42: 時間外 | CT42: =IF(Q40="作業者2",K43-K40,0) | CZ42: 時間外 | DD42: =IF(Q40="作業者3",K43-K40,0) | DJ42: 時間外 | DN42: =IF(Q40="作業者4",K43-K40,0) | DT42: 時間外 | DX42: =IF(Q40="作業者5",K43-K40,0)
...

Sheet 作業報告書 (END)
B2: 月／日 | E2: 移 動 | H2: 作業内 (平日) | K2: 作業外 (平日) | N2: 休日 | Q2: 作業者 | T2: 場 所 | W2: 作 業 内 容 | CF2: 所要時間 作業者1 | CP2: 所要時間 作業者2 | CZ2: 所要時間 作業者3 | DJ2: 所要時間 作業者4 | DT2: 所要時間 作業者5
CF4: 移動 | CJ4: =IF(Q4="作業者1",E7-E4,0) | CP4: 移動 | CT4: =IF(Q4="作業者2",E7-E4,0) | CZ4: 移動 | DD4: =IF(Q4="作業者3",E7-E4,0) | DJ4: 移動 | DN4: =IF(Q4="作業者4",E7-E4,0) | DT4: 移動 | DX4: =IF(Q4="作業者5",E7-E4,0)
F5: ～ | I5: ～ | L5: ～ | O5: ～ | CF5: 時間内 | CJ5: =IF(Q4="作業者1",H7-H4,0) | CP5: 時間内 | CT5: =IF(Q4="作業者2",H7-H4,0) | CZ5: 時間内 | DD5: =IF(Q4="作業者3",H7-H4,0) | DJ5: 時間内 | DN5: =IF(Q4="作業者4",H7-H4,0) | DT5: 時間内 | DX5: =IF(Q4="作業者5",H7-H4,0)
CF6: 時間外 | CJ6: =IF(Q4="作業者1",K7-K4,0) | CP6: 時間外 | CT6: =IF(Q4="作業者2",K7-K4,0) | CZ6: 時間外 | DD6: =IF(Q4="作業者3",K7-K4,0) | DJ6: 時間外 | DN6: =IF(Q4="作業者4",K7-K4,0) | DT6: 時間外 | DX6: =IF(Q4="作業者5",K7-K4,0)
CF7: 休日 | CJ7: =IF(Q4="作業者1",N7-N4,0) | CP7: 休日 | CT7: =IF(Q4="作業者2",N7-N4,0) | CZ7: 休日 | DD7: =IF(Q4="作業者3",N7-N4,0) | DJ7: 休日 | DN7: =IF(Q4="作業者4",N7-N4,0) | DT7: 休日 | DX7: =IF(Q4="作業者5",N7-N4,0)
CF8: 移動 | CJ8: =IF(Q8="作業者1",E11-E8,0) | CP8: 移動 | CT8: =IF(Q8="作業者2",E11-E8,0) | CZ8: 移動 | DD8: =IF(Q8="作業者3",E11-E8,0) | DJ8: 移動 | DN8: =IF(Q8="作業者4",E11-E8,0) | DT8: 移動 | DX8: =IF(Q8="作業者5",E11-E8,0)
F9: ～ | I9: ～ | L9: ～ | O9: ～ | CF9: 時間内 | CJ9: =IF(Q8="作業者1",H11-H8,0) | CP9: 時間内 | CT9: =IF(Q8="作業者2",H11-H8,0) | CZ9: 時間内 | DD9: =IF(Q8="作業者3",H11-H8,0) | DJ9: 時間内 | DN9: =IF(Q8="作業者4",H11-H8,0) | DT9: 時間内 | DX9: =IF(Q8="作業者5",H11-H8,0)
CF10: 時間外 | CJ10: =IF(Q8="作業者1",K11-K8,0) | CP10: 時間外 | CT10: =IF(Q8="作業者2",K11-K8,0) | CZ10: 時間外 | DD10: =IF(Q8="作業者3",K11-K8,0) | DJ10: 時間外 | DN10: =IF(Q8="作業者4",K11-K8,0) | DT10: 時間外 | DX10: =IF(Q8="作業者5",K11-K8,0)
CF11: 休日 | CJ11: =IF(Q8="作業者1",N11-N8,0) | CP11: 休日 | CT11: =IF(Q8="作業者2",N11-N8,0) | CZ11: 休日 | DD11: =IF(Q8="作業者3",N11-N8,0) | DJ11: 休日 | DN11: =IF(Q8="作業者4",N11-N8,0) | DT11: 休日 | DX11: =IF(Q8="作業者5",N11-N8,0)
CF12: 移動 | CJ12: =IF(Q12="作業者1",E15-E12,0) | CP12: 移動 | CT12: =IF(Q12="作業者2",E15-E12,0) | CZ12: 移動 | DD12: =IF(Q12="作業者3",E15-E12,0) | DJ12: 移動 | DN12: =IF(Q12="作業者4",E15-E12,0) | DT12: 移動 | DX12: =IF(Q12="作業者5",E15-E12,0)
F13: ～ | I13: ～ | L13: ～ | O13: ～ | CF13: 時間内 | CJ13: =IF(Q12="作業者1",H15-H12,0) | CP13: 時間内 | CT13: =IF(Q12="作業者2",H15-H12,0) | CZ13: 時間内 | DD13: =IF(Q12="作業者3",H15-H12,0) | DJ13: 時間内 | DN13: =IF(Q12="作業者4",H15-H12,0) | DT13: 時間内 | DX13: =IF(Q12="作業者5",H15-H12,0)
CF14: 時間外 | CJ14: =IF(Q12="作業者1",K15-K12,0) | CP14: 時間外 | CT14: =IF(Q12="作業者2",K15-K12,0) | CZ14: 時間外 | DD14: =IF(Q12="作業者3",K15-K12,0) | DJ14: 時間外 | DN14: =IF(Q12="作業者4",K15-K12,0) | DT14: 時間外 | DX14: =IF(Q12="作業者5",K15-K12,0)
CF15: 休日 | CJ15: =IF(Q12="作業者1",N15-N12,0) | CP15: 休日 | CT15: =IF(Q12="作業者2",N15-N12,0) | CZ15: 休日 | DD15: =IF(Q12="作業者3",N15-N12,0) | DJ15: 休日 | DN15: =IF(Q12="作業者4",N15-N12,0) | DT15: 休日 | DX15: =IF(Q12="作業者5",N15-N12,0)
CF16: 移動 | CJ16: =IF(Q16="作業者1",E19-E16,0) | CP16: 移動 | CT16: =IF(Q16="作業者2",E19-E16,0) | CZ16: 移動 | DD16: =IF(Q16="作業者3",E19-E16,0) | DJ16: 移動 | DN16: =IF(Q16="作業者4",E19-E16,0) | DT16: 移動 | DX16: =IF(Q16="作業者5",E19-E16,0)
F17: ～ | I17: ～ | L17: ～ | O17: ～ | CF17: 時間内 | CJ17: =IF(Q16="作業者1",H19-H16,0) | CP17: 時間内 | CT17: =IF(Q16="作業者2",H19-H16,0) | CZ17: 時間内 | DD17: =IF(Q16="作業者3",H19-H16,0) | DJ17: 時間内 | DN17: =IF(Q16="作業者4",H19-H16,0) | DT17: 時間内 | DX17: =IF(Q16="作業者5",H19-H16,0)
CF18: 時間外 | CJ18: =IF(Q16="作業者1",K19-K16,0) | CP18: 時間外 | CT18: =IF(Q16="作業者2",K19-K16,0) | CZ18: 時間外 | DD18: =IF(Q16="作業者3",K19-K16,0) | DJ18: 時間外 | DN18: =IF(Q16="作業者4",K19-K16,0) | DT18: 時間外 | DX18: =IF(Q16="作業者5",K19-K16,0)
CF19: 休日 | CJ19: =IF(Q16="作業者1",N19-N16,0) | CP19: 休日 | CT19: =IF(Q16="作業者2",N19-N16,0) | CZ19: 休日 | DD19: =IF(Q16="作業者3",N19-N16,0) | DJ19: 休日 | DN19: =IF(Q16="作業者4",N19-N16,0) | DT19: 休日 | DX19: =IF(Q16="作業者5",N19-N16,0)
CF20: 移動 | CJ20: =IF(Q20="作業者1",E23-E20,0) | CP20: 移動 | CT20: =IF(Q20="作業者2",E23-E20,0) | CZ20: 移動 | DD20: =IF(Q20="作業者3",E23-E20,0) | DJ20: 移動 | DN20: =IF(Q20="作業者4",E23-E20,0) | DT20: 移動 | DX20: =IF(Q20="作業者5",E23-E20,0)
F21: ～ | I21: ～ | L21: ～ | O21: ～ | CF21: 時間内 | CJ21: =IF(Q20="作業者1",H23-H20,0) | CP21: 時間内 | CT21: =IF(Q20="作業者2",H23-H20,0) | CZ21: 時間内 | DD21: =IF(Q20="作業者3",H23-H20,0) | DJ21: 時間内 | DN21: =IF(Q20="作業者4",H23-H20,0) | DT21: 時間内 | DX21: =IF(Q20="作業者5",H23-H20,0)
CF22: 時間外 | CJ22: =IF(Q20="作業者1",K23-K20,0) | CP22: 時間外 | CT22: =IF(Q20="作業者2",K23-K20,0) | CZ22: 時間外 | DD22: =IF(Q20="作業者3",K23-K20,0) | DJ22: 時間外 | DN22: =IF(Q20="作業者4",K23-K20,0) | DT22: 時間外 | DX22: =IF(Q20="作業者5",K23-K20,0)
CF23: 休日 | CJ23: =IF(Q20="作業者1",N23-N20,0) | CP23: 休日 | CT23: =IF(Q20="作業者2",N23-N20,0) | CZ23: 休日 | DD23: =IF(Q20="作業者3",N23-N20,0) | DJ23: 休日 | DN23: =IF(Q20="作業者4",N23-N20,0) | DT23: 休日 | DX23: =IF(Q20="作業者5",N23-N20,0)
CF24: 移動 | CJ24: =IF(Q24="作業者1",E27-E24,0) | CP24: 移動 | CT24: =IF(Q24="作業者2",E27-E24,0) | CZ24: 移動 | DD24: =IF(Q24="作業者3",E27-E24,0) | DJ24: 移動 | DN24: =IF(Q24="作業者4",E27-E24,0) | DT24: 移動 | DX24: =IF(Q24="作業者5",E27-E24,0)
F25: ～ | I25: ～ | L25: ～ | O25: ～ | CF25: 時間内 | CJ25: =IF(Q24="作業者1",H27-H24,0) | CP25: 時間内 | CT25: =IF(Q24="作業者2",H27-H24,0) | CZ25: 時間内 | DD25: =IF(Q24="作業者3",H27-H24,0) | DJ25: 時間内 | DN25: =IF(Q24="作業者4",H27-H24,0) | DT25: 時間内 | DX25: =IF(Q24="作業者5",H27-H24,0)
CF26: 時間外 | CJ26: =IF(Q24="作業者1",K27-K24,0) | CP26: 時間外 | CT26: =IF(Q24="作業者2",K27-K24,0) | CZ26: 時間外 | DD26: =IF(Q24="作業者3",K27-K24,0) | DJ26: 時間外 | DN26: =IF(Q24="作業者4",K27-K24,0) | DT26: 時間外 | DX26: =IF(Q24="作業者5",K27-K24,0)
CF27: 休日 | CJ27: =IF(Q24="作業者1",N27-N24,0) | CP27: 休日 | CT27: =IF(Q24="作業者2",N27-N24,0) | CZ27: 休日 | DD27: =IF(Q24="作業者3",N27-N24,0) | DJ27: 休日 | DN27: =IF(Q24="作業者4",N27-N24,0) | DT27: 休日 | DX27: =IF(Q24="作業者5",N27-N24,0)
CF28: 移動 | CJ28: =IF(Q28="作業者1",E31-E28,0) | CP28: 移動 | CT28: =IF(Q28="作業者2",E31-E28,0) | CZ28: 移動 | DD28: =IF(Q28="作業者3",E31-E28,0) | DJ28: 移動 | DN28: =IF(Q28="作業者4",E31-E28,0) | DT28: 移動 | DX28: =IF(Q28="作業者5",E31-E28,0)
F29: ～ | I29: ～ | L29: ～ | O29: ～ | CF29: 時間内 | CJ29: =IF(Q28="作業者1",H31-H28,0) | CP29: 時間内 | CT29: =IF(Q28="作業者2",H31-H28,0) | CZ29: 時間内 | DD29: =IF(Q28="作業者3",H31-H28,0) | DJ29: 時間内 | DN29: =IF(Q28="作業者4",H31-H28,0) | DT29: 時間内 | DX29: =IF(Q28="作業者5",H31-H28,0)
CF30: 時間外 | CJ30: =IF(Q28="作業者1",K31-K28,0) | CP30: 時間外 | CT30: =IF(Q28="作業者2",K31-K28,0) | CZ30: 時間外 | DD30: =IF(Q28="作業者3",K31-K28,0) | DJ30: 時間外 | DN30: =IF(Q28="作業者4",K31-K28,0) | DT30: 時間外 | DX30: =IF(Q28="作業者5",K31-K28,0)
CF31: 休日 | CJ31: =IF(Q28="作業者1",N31-N28,0) | CP31: 休日 | CT31: =IF(Q28="作業者2",N31-N28,0) | CZ31: 休日 | DD31: =IF(Q28="作業者3",N31-N28,0) | DJ31: 休日 | DN31: =IF(Q28="作業者4",N31-N28,0) | DT31: 休日 | DX31: =IF(Q28="作業者5",N31-N28,0)
CF32: 移動 | CJ32: =IF(Q32="作業者1",E35-E32,0) | CP32: 移動 | CT32: =IF(Q32="作業者2",E35-E32,0) | CZ32: 移動 | DD32: =IF(Q32="作業者3",E35-E32,0) | DJ32: 移動 | DN32: =IF(Q32="作業者4",E35-E32,0) | DT32: 移動 | DX32: =IF(Q32="作業者5",E35-E32,0)
F33: ～ | I33: ～ | L33: ～ | O33: ～ | CF33: 時間内 | CJ33: =IF(Q32="作業者1",H35-H32,0) | CP33: 時間内 | CT33: =IF(Q32="作業者2",H35-H32,0) | CZ33: 時間内 | DD33: =IF(Q32="作業者3",H35-H32,0) | DJ33: 時間内 | DN33: =IF(Q32="作業者4",H35-H32,0) | DT33: 時間内 | DX33: =IF(Q32="作業者5",H35-H32,0)
CF34: 時間外 | CJ34: =IF(Q32="作業者1",K35-K32,0) | CP34: 時間外 | CT34: =IF(Q32="作業者2",K35-K32,0) | CZ34: 時間外 | DD34: =IF(Q32="作業者3",K35-K32,0) | DJ34: 時間外 | DN34: =IF(Q32="作業者4",K35-K32,0) | DT34: 時間外 | DX34: =IF(Q32="作業者5",K35-K32,0)
CF35: 休日 | CJ35: =IF(Q32="作業者1",N35-N32,0) | CP35: 休日 | CT35: =IF(Q32="作業者2",N35-N32,0) | CZ35: 休日 | DD35: =IF(Q32="作業者3",N35-N32,0) | DJ35: 休日 | DN35: =IF(Q32="作業者4",N35-N32,0) | DT35: 休日 | DX35: =IF(Q32="作業者5",N35-N32,0)
CF36: 移動 | CJ36: =IF(Q36="作業者1",E39-E36,0) | CP36: 移動 | CT36: =IF(Q36="作業者2",E39-E36,0) | CZ36: 移動 | DD36: =IF(Q36="作業者3",E39-E36,0) | DJ36: 移動 | DN36: =IF(Q36="作業者4",E39-E36,0) | DT36: 移動 | DX36: =IF(Q36="作業者5",E39-E36,0)
F37: ～ | I37: ～ | L37: ～ | O37: ～ | CF37: 時間内 | CJ37: =IF(Q36="作業者1",H39-H36,0) | CP37: 時間内 | CT37: =IF(Q36="作業者2",H39-H36,0) | CZ37: 時間内 | DD37: =IF(Q36="作業者3",H39-H36,0) | DJ37: 時間内 | DN37: =IF(Q36="作業者4",H39-H36,0) | DT37: 時間内 | DX37: =IF(Q36="作業者5",H39-H36,0)
CF38: 時間外 | CJ38: =IF(Q36="作業者1",K39-K36,0) | CP38: 時間外 | CT38: =IF(Q36="作業者2",K39-K36,0) | CZ38: 時間外 | DD38: =IF(Q36="作業者3",K39-K36,0) | DJ38: 時間外 | DN38: =IF(Q36="作業者4",K39-K36,0) | DT38: 時間外 | DX38: =IF(Q36="作業者5",K39-K36,0)
CF39: 休日 | CJ39: =IF(Q36="作業者1",N39-N36,0) | CP39: 休日 | CT39: =IF(Q36="作業者2",N39-N36,0) | CZ39: 休日 | DD39: =IF(Q36="作業者3",N39-N36,0) | DJ39: 休日 | DN39: =IF(Q36="作業者4",N39-N36,0) | DT39: 休日 | DX39: =IF(Q36="作業者5",N39-N36,0)
CF40: 移動 | CJ40: =IF(Q40="作業者1",E43-E40,0) | CP40: 移動 | CT40: =IF(Q40="作業者2",E43-E40,0) | CZ40: 移動 | DD40: =IF(Q40="作業者3",E43-E40,0) | DJ40: 移動 | DN40: =IF(Q40="作業者4",E43-E40,0) | DT40: 移動 | DX40: =IF(Q40="作業者5",E43-E40,0)
F41: ～ | I41: ～ | L41: ～ | O41: ～ | CF41: 時間内 | CJ41: =IF(Q40="作業者1",H43-H40,0) | CP41: 時間内 | CT41: =IF(Q40="作業者2",H43-H40,0) | CZ41: 時間内 | DD41: =IF(Q40="作業者3",H43-H40,0) | DJ41: 時間内 | DN41: =IF(Q40="作業者4",H43-H40,0) | DT41: 時間内 | DX41: =IF(Q40="作業者5",H43-H40,0)
CF42: 時間外 | CJ42: =IF(Q40="作業者1",K43-K40,0) | CP42: 時間外 | CT42: =IF(Q40="作業者2",K43-K40,0) | CZ42: 時間外 | DD42: =IF(Q40="作業者3",K43-K40,0) | DJ42: 時間外 | DN42: =IF(Q40="作業者4",K43-K40,0) | DT42: 時間外 | DX42: =IF(Q40="作業者5",K43-K40,0)
...

Sheet 材料持出表
A1: 船 名 | D1: =作業報告書!C5 | P1: 科 目 | S1: =作業報告書!Y5 | AE1: 型 名 | AT1: 完成月日
A2: 氏 名 | G2: 平 日 時 間 (内) | M2: 工 賃(@7,000) | S2: 平 日 時 間 (外) | Y2: 休 日 労 働 時 間 | AE2: 工 賃(@8,400) | AK2: 移 動 時 間 | AO2: 移動費(×0.8) | AU2: 備 考
G3: =SUM('作業報告書:作業報告書 (END)'!CJ139) | M3: =(G3*24)*7000 | S3: =SUM('作業報告書:作業報告書 (END)'!CJ140) | Y3: =SUM('作業報告書:作業報告書 (END)'!CJ141) | AE3: =(S3*24+Y3*24)*8400 | AK3: =SUM('作業報告書:作業報告書 (END)'!CJ138) | AO3: =(AK3*24)*5600
G4: =SUM('作業報告書:作業報告書 (END)'!CT139) | M4: =(G4*24)*7000 | S4: =SUM('作業報告書:作業報告書 (END)'!CT140) | Y4: =SUM('作業報告書:作業報告書 (END)'!CT141) | AE4: =(S4*24+Y4*24)*8400 | AK4: =SUM('作業報告書:作業報告書 (END)'!CT138) | AO4: =(AK4*24)*5600
G5: =SUM('作業報告書:作業報告書 (END)'!DD139) | M5: =(G5*24)*7000 | S5: =SUM('作業報告書:作業報告書 (END)'!DD140) | Y5: =SUM('作業報告書:作業報告書 (END)'!DD141) | AE5: =(S5*24+Y5*24)*8400 | AK5: =SUM('作業報告書:作業報告書 (END)'!DD138) | AO5: =(AK5*24)*5600
G6: =SUM('作業報告書:作業報告書 (END)'!DN139) | M6: =(G6*24)*7000 | S6: =SUM('作業報告書:作業報告書 (END)'!DN140) | Y6: =SUM('作業報告書:作業報告書 (END)'!DN141) | AE6: =(S6*24+Y6*24)*8400 | AK6: =SUM('作業報告書:作業報告書 (END)'!DN138) | AO6: =(AK6*24)*5600
G7: =SUM('作業報告書:作業報告書 (END)'!DX139) | M7: =(G7*24)*7000 | S7: =SUM('作業報告書:作業報告書 (END)'!DX140) | Y7: =SUM('作業報告書:作業報告書 (END)'!DX141) | AE7: =(S7*24+Y7*24)*8400 | AK7: =SUM('作業報告書:作業報告書 (END)'!DX138) | AO7: =(AK7*24)*5600
M8: =(G8*24)*7000 | AE8: =(S8*24+Y8*24)*8400 | AO8: =(AK8*24)*5600
A9: 合計 | G9: =SUM(G3:L8) | M9: =SUM(M3:R8) | S9: =SUM(S3:X8) | Y9: =SUM(Y3:AD8) | AE9: =SUM(AE3:AJ8) | AK9: =SUM(AK3:AN8) | AO9: =SUM(AO3:AT8)
A10: 材 料 持 出 表
A11: 月 / 日 | E11: 品 名 | M11: 型 式 | U11: 在 庫 | X11: 仕 入 先 | AB11: 数 量 | AF11: 仕 入 単 価 | AJ11: 仕 入 合 計 | AO11: 売 値 単 価 | AS11: 売 値 合 計 | AX11: 送 料
AJ12: =SUM(AF12*AB12) | AS12: =SUM(AO12*AB12)
AJ13: =SUM(AF13*AB13) | AS13: =SUM(AO13*AB13)
AJ14: =SUM(AF14*AB14) | AS14: =SUM(AO14*AB14)
AJ15: =SUM(AF15*AB15) | AS15: =SUM(AO15*AB15)
AJ16: =SUM(AF16*AB16) | AS16: =SUM(AO16*AB16)
AJ17: =SUM(AF17*AB17) | AS17: =SUM(AO17*AB17)
AJ18: =SUM(AF18*AB18) | AS18: =SUM(AO18*AB18)
AJ19: =SUM(AF19*AB19) | AS19: =SUM(AO19*AB19)
AJ20: =SUM(AF20*AB20) | AS20: =SUM(AO20*AB20)
AJ21: =SUM(AF21*AB21) | AS21: =SUM(AO21*AB21)
AJ22: =SUM(AF22*AB22) | AS22: =SUM(AO22*AB22)
AJ23: =SUM(AF23*AB23) | AS23: =SUM(AO23*AB23)
AJ24: =SUM(AF24*AB24) | AS24: =SUM(AO24*AB24)
U25: 持 出 者 | AF25: 仕 入 合 計 | AO25: 売 値 合 計
D27: ✓ | H27: ﾓﾉﾀﾛｳ
D28: 在庫外 | H28: ｱﾏｿﾞﾝ
H29: ﾊｰﾄﾞｽﾄｯｸ
H30: JRC
H31: 神田ｴﾚｸﾄﾛﾆｸｽ
H32: 大野電子
H33: 緑星社
H34: 三菱電機特機ｼｽﾃﾑ㈱
H35: ｴﾝﾁｮｳ
H36: RS
H37: ﾏﾙﾂ
H38: ｴﾃﾞｨｵﾝ
H39: K'sﾃﾞﾝｷ
H40: ｶｰﾏ

Sheet 材料持出表 (2)
A1: 材 料 持 出 表
A2: 月 / 日 | E2: 品 名 | M2: 型 式 | U2: 在 庫 | X2: 仕 入 先 | AB2: 数 量 | AF2: 仕 入 単 価 | AJ2: 仕 入 合 計 | AO2: 売 値 単 価 | AS2: 売 値 合 計 | AX2: 送 料
AJ3: =SUM(AF3*AB3) | AS3: =SUM(AO3*AB3)
AJ4: =SUM(AF4*AB4) | AS4: =SUM(AO4*AB4)
AJ5: =SUM(AF5*AB5) | AS5: =SUM(AO5*AB5)
AJ6: =SUM(AF6*AB6) | AS6: =SUM(AO6*AB6)
AJ7: =SUM(AF7*AB7) | AS7: =SUM(AO7*AB7)
AJ8: =SUM(AF8*AB8) | AS8: =SUM(AO8*AB8)
AJ9: =SUM(AF9*AB9) | AS9: =SUM(AO9*AB9)
AJ10: =SUM(AF10*AB10) | AS10: =SUM(AO10*AB10)
AJ11: =SUM(AF11*AB11) | AS11: =SUM(AO11*AB11)
AJ12: =SUM(AF12*AB12) | AS12: =SUM(AO12*AB12)
AJ13: =SUM(AF13*AB13) | AS13: =SUM(AO13*AB13)
AJ14: =SUM(AF14*AB14) | AS14: =SUM(AO14*AB14)
... AJ25: =SUM(AF25*AB25) | AS25: =SUM(AO25*AB25)
U26: 持 出 者 | AF26: 仕 入 合 計 | AO26: 売 値 合 計
D28: ✓ | H28: ﾓﾉﾀﾛｳ
D29: 在庫外 | H29: ｱﾏｿﾞﾝ
H30: ﾊｰﾄﾞｽﾄｯｸ
H31: JRC
H32: 神田ｴﾚｸﾄﾛﾆｸｽ
H33: 大野電子
H34: 緑星社
H35: 三菱電機特機ｼｽﾃﾑ㈱
H36: ｴﾝﾁｮｳ
H37: RS
H38: ﾏﾙﾂ
H39: ｴﾃﾞｨｵﾝ
H40: K'sﾃﾞﾝｷ
H41: ｶｰﾏ

Sheet 材料持出表 (3)
A1: 材 料 持 出 表
A2: 月 / 日 | E2: 品 名 | M2: 型 式 | U2: 在 庫 | X2: 仕 入 先 | AB2: 数 量 | AF2: 仕 入 単 価 | AJ2: 仕 入 合 計 | AO2: 売 値 単 価 | AS2: 売 値 合 計 | AX2: 送 料
AJ3: =SUM(AF3*AB3) | AS3: =SUM(AO3*AB3)
AJ4: =SUM(AF4*AB4) | AS4: =SUM(AO4*AB4)
AJ5: =SUM(AF5*AB5) | AS5: =SUM(AO5*AB5)
AJ6: =SUM(AF6*AB6) | AS6: =SUM(AO6*AB6)
AJ7: =SUM(AF7*AB7) | AS7: =SUM(AO7*AB7)
AJ8: =SUM(AF8*AB8) | AS8: =SUM(AO8*AB8)
AJ9: =SUM(AF9*AB9) | AS9: =SUM(AO9*AB9)
AJ10: =SUM(AF10*AB10) | AS10: =SUM(AO10*AB10)
AJ11: =SUM(AF11*AB11) | AS11: =SUM(AO11*AB11)
AJ12: =SUM(AF12*AB12) | AS12: =SUM(AO12*AB12)
AJ13: =SUM(AF13*AB13) | AS13: =SUM(AO13*AB13)
AJ14: =SUM(AF14*AB14) | AS14: =SUM(AO14*AB14)
... AJ25: =SUM(AF25*AB25) | AS25: =SUM(AO25*AB25)
U26: 持 出 者 | AF26: 仕 入 合 計 | AO26: 売 値 合 計
D28: ✓ | H28: ﾓﾉﾀﾛｳ
H29: ｱﾏｿﾞﾝ
H30: ﾊｰﾄﾞｽﾄｯｸ
H31: JRC
H32: 神田ｴﾚｸﾄﾛﾆｸｽ
H33: 大野電子
H34: 緑星社
H35: 三菱電機特機ｼｽﾃﾑ㈱
H36: ｴﾝﾁｮｳ
H37: RS
H38: ﾏﾙﾂ
H39: ｴﾃﾞｨｵﾝ
H40: K'sﾃﾞﾝｷ
H41: ｶｰﾏ

Sheet 材料持出表 (4)
A1: 材 料 持 出 表
A2: 月 / 日 | E2: 品 名 | M2: 型 式 | U2: 在 庫 | X2: 仕 入 先 | AB2: 数 量 | AF2: 仕 入 単 価 | AJ2: 仕 入 合 計 | AO2: 売 値 単 価 | AS2: 売 値 合 計 | AX2: 送 料
AJ3: =SUM(AF3*AB3) | AS3: =SUM(AO3*AB3)
AJ4: =SUM(AF4*AB4) | AS4: =SUM(AO4*AB4)
AJ5: =SUM(AF5*AB5) | AS5: =SUM(AO5*AB5)
AJ6: =SUM(AF6*AB6) | AS6: =SUM(AO6*AB6)
AJ7: =SUM(AF7*AB7) | AS7: =SUM(AO7*AB7)
AJ8: =SUM(AF8*AB8) | AS8: =SUM(AO8*AB8)
AJ9: =SUM(AF9*AB9) | AS9: =SUM(AO9*AB9)
AJ10: =SUM(AF10*AB10) | AS10: =SUM(AO10*AB10)
AJ11: =SUM(AF11*AB11) | AS11: =SUM(AO11*AB11)
AJ12: =SUM(AF12*AB12) | AS12: =SUM(AO12*AB12)
AJ13: =SUM(AF13*AB13) | AS13: =SUM(AO13*AB13)
AJ14: =SUM(AF14*AB14) | AS14: =SUM(AO14*AB14)
... AJ25: =SUM(AF25*AB25) | AS25: =SUM(AO25*AB25)
